Workbook

Sheet Base Libro Banco  
A2: FECHA | B2: MES | C2: AÑO | D2: CONCEPTO | E2: UNIDAD DE NEGOCIO | F2: DETALLE | G2: PROVEEDOR | H2: TIPO | I2: n cheque | J2: DEBE (INGRESO) | K2: HABER (EGRESO) | L2: IVA | M2: FCATURADO A SAS | N2: Fecha ingreso tarjeta | O2: Monto de ingreso | Q2: Concepto | R2: Unidad de negocio | S2: Tipo
A3: 44958 | B3: =MONTH(A3) -> 2 | C3: =YEAR((A3)) -> 2023 | D3: pago cliente | E3: Taller | F3: Miren cipolla casual | H3: Transferencia | J3: 19500 | Q3: ='Base Libro Caja'!Q3 -> Pago cliente | R3: Personal | S3: Cheque de terceros
A4: 45133 | B4: =MONTH(A4) -> 7 | C4: =YEAR((A4)) -> 2023 | D4: Pago cliente | E4: Taller | F4: Alemandi Banina | H4: Transferencia | J4: 54400 | Q4: ='Base Libro Caja'!Q4 -> Impuestos Municipales | R4: Taller | S4: Transferencia
A5: 45134 | B5: =MONTH(A5) -> 7 | C5: =YEAR((A5)) -> 2023 | D5: Pago cliente | E5: Taller | F5: Cele | H5: Transferencia | J5: 73100 | Q5: ='Base Libro Caja'!Q5 -> Saldo inicial | S5: Tarjeta
A6: 45134 | B6: =MONTH(A6) -> 7 | C6: =YEAR((A6)) -> 2023 | D6: Pago cliente | E6: Taller | F6: Sandra carrara | H6: Cheque de terceros | I6: 1575924 | J6: 115000 | Q6: ='Base Libro Caja'!Q6 -> Pago cliente casual | S6: Personal
A7: 45134 | B7: =MONTH(A7) -> 7 | C7: =YEAR((A7)) -> 2023 | D7: Pago cliente | E7: Taller | F7: Bernard abu grillo | H7: Transferencia | J7: 80700 | Q7: ='Base Libro Caja'!Q7 -> Librería | S7: E-cheq
A8: 45135 | B8: =MONTH(A8) -> 7 | C8: =YEAR((A8)) -> 2023 | D8: Pago cliente | E8: Taller | F8: Martin Jose | H8: Transferencia | J8: 68150 | Q8: ='Base Libro Caja'!Q8 -> Articulos de limpieza | S8: Efectivo Personal
A9: 45136 | B9: =MONTH(A9) -> 7 | C9: =YEAR((A9)) -> 2023 | D9: Pago cliente | E9: Taller | F9: Castro Martin | H9: Transferencia | J9: 50500 | Q9: ='Base Libro Caja'!Q9 -> Combustible
A10: 45138 | B10: =MONTH(A10) -> 7 | C10: =YEAR((A10)) -> 2023 | D10: Pago cliente | E10: Taller | F10: Juan Pablo Lang | H10: Transferencia | J10: 124220 | Q10: ='Base Libro Caja'!Q10 -> Ingreso a Caja grande
A11: 45139 | B11: =MONTH(A11) -> 8 | C11: =YEAR((A11)) -> 2023 | D11: Pago cliente | E11: Taller | F11: Cane Emiliano | H11: Cheque de terceros | J11: 100000 | Q11: ='Base Libro Caja'!Q11 -> Ingreso a Caja chica
A12: 45139 | B12: =MONTH(A12) -> 8 | C12: =YEAR((A12)) -> 2023 | D12: Pago cliente | E12: Taller | F12: Cane Emiliano | H12: Cheque de terceros | J12: 18792 | Q12: ='Base Libro Caja'!Q12 -> Pago proveedor
A13: 45141 | B13: =MONTH(A13) -> 8 | C13: =YEAR((A13)) -> 2023 | D13: Pago cliente | E13: Taller | F13: Ana Paula Goico | H13: Transferencia | J13: 50000 | Q13: ='Base Libro Caja'!Q13 -> Personal
A14: 45141 | B14: =MONTH(A14) -> 8 | C14: =YEAR((A14)) -> 2023 | D14: Pago cliente | E14: Taller | F14: Duran | H14: Transferencia | J14: 51600 | Q14: ='Base Libro Caja'!Q14 -> Gastos generales
A15: 45142 | B15: =MONTH(A15) -> 8 | C15: =YEAR((A15)) -> 2023 | D15: Pago cliente | E15: Taller | F15: Isasi | H15: Transferencia | J15: 22000 | Q15: ='Base Libro Caja'!Q15 -> Comisiones
A16: 45142 | B16: =MONTH(A16) -> 8 | C16: =YEAR((A16)) -> 2023 | D16: Pago cliente | E16: Taller | F16: Gimenez | H16: Cheque de terceros | J16: 30000 | Q16: ='Base Libro Caja'!Q16 -> Vuelto cliente
A17: 45146 | B17: =MONTH(A17) -> 8 | C17: =YEAR((A17)) -> 2023 | D17: Personal | E17: Personal | F17: Mutual | H17: Transferencia | K17: 107970 | Q17: Servicios
A18: 45146 | B18: =MONTH(A18) -> 8 | C18: =YEAR((A18)) -> 2023 | D18: Pago cliente | E18: Taller | F18: palloni | H18: Cheque de terceros | J18: 87120 | Q18: Sueldos
A19: 45146 | B19: =MONTH(A19) -> 8 | C19: =YEAR((A19)) -> 2023 | D19: Pago cliente | E19: Taller | F19: palloni | H19: Cheque de terceros | J19: 87120 | Q19: Honorarios
A20: 45146 | B20: =MONTH(A20) -> 8 | C20: =YEAR((A20)) -> 2023 | D20: Pago cliente | E20: Taller | F20: palloni | H20: Cheque de terceros | J20: 87120 | Q20: Sueldo administrativo
A21: 45147 | B21: =MONTH(A21) -> 8 | C21: =YEAR((A21)) -> 2023 | D21: Pago cliente | E21: Taller | F21: Rodriguez | H21: Transferencia | J21: 121900 | Q21: Sueldo mecánicos
A22: 45147 | B22: =MONTH(A22) -> 8 | C22: =YEAR((A22)) -> 2023 | D22: Pago cliente | E22: Taller | F22: Calderón | H22: Transferencia | J22: 17693 | Q22: Herramientas / bienes de uso
A23: 45147 | B23: =MONTH(A23) -> 8 | C23: =YEAR((A23)) -> 2023 | D23: Pago cliente | E23: Taller | F23: mansuino | H23: Transferencia | J23: 10500 | Q23: Servicios de terceros
A24: 45147 | B24: =MONTH(A24) -> 8 | C24: =YEAR((A24)) -> 2023 | D24: Pago cliente | E24: Taller | F24: Manito | H24: Transferencia | J24: 52900 | Q24: Calco
A25: 45148 | B25: =MONTH(A25) -> 8 | C25: =YEAR((A25)) -> 2023 | D25: Pago cliente | E25: Taller | F25: bocha | H25: Transferencia | J25: 21800 | Q25: Monotributo
A26: 45149 | B26: =MONTH(A26) -> 8 | C26: =YEAR((A26)) -> 2023 | D26: Pago cliente | E26: Taller | F26: bertaina | H26: Transferencia | J26: 53762.5 | Q26: Publicidad
A27: 45153 | B27: =MONTH(A27) -> 8 | C27: =YEAR((A27)) -> 2023 | D27: Pago cliente | E27: Taller | F27: irouleguy | H27: Transferencia | J27: 36800 | Q27: Ropa
A28: 45153 | B28: =MONTH(A28) -> 8 | C28: =YEAR((A28)) -> 2023 | D28: Pago cliente | E28: Taller | F28: Cane Emiliano | H28: Cheque de terceros | J28: 35000 | Q28: Impuestos AFIP
A29: 45153 | B29: =MONTH(A29) -> 8 | C29: =YEAR((A29)) -> 2023 | D29: Pago cliente | E29: Taller | F29: Cane Emiliano | H29: Cheque de terceros | J29: 28000 | Q29: Gastos tarjetas
A30: 45153 | B30: =MONTH(A30) -> 8 | C30: =YEAR((A30)) -> 2023 | D30: Pago cliente | E30: Taller | F30: mainero | H30: Transferencia | J30: 76750 | Q30: Gastos bancarios
A31: 45153 | B31: =MONTH(A31) -> 8 | C31: =YEAR((A31)) -> 2023 | D31: Pago cliente | E31: Taller | F31: suarez | H31: Cheque de terceros | J31: 102615
A32: 45154 | B32: =MONTH(A32) -> 8 | C32: =YEAR((A32)) -> 2023 | D32: Pago cliente | E32: Taller | F32: Fiori Martin | H32: Transferencia | J32: 25000
A33: 45155 | B33: =MONTH(A33) -> 8 | C33: =YEAR((A33)) -> 2023 | D33: Pago cliente | E33: Taller | F33: moreti Ani | H33: Cheque de terceros | J33: 75000
A34: 45155 | B34: =MONTH(A34) -> 8 | C34: =YEAR((A34)) -> 2023 | D34: Pago cliente | E34: Taller | F34: moreti Ani | H34: Cheque de terceros | J34: 60000
A35: 45155 | B35: =MONTH(A35) -> 8 | C35: =YEAR((A35)) -> 2023 | D35: Pago cliente | E35: Taller | F35: gigante | H35: Cheque de terceros | J35: 29460
A36: 45155 | B36: =MONTH(A36) -> 8 | C36: =YEAR((A36)) -> 2023 | D36: Pago proveedor | E36: Taller | G36: Repuestos Serrano | H36: Cheque de terceros | K36: 102615
A37: 45155 | B37: =MONTH(A37) -> 8 | C37: =YEAR((A37)) -> 2023 | D37: Pago cliente | E37: Taller | F37: Angeleri | H37: Transferencia | J37: 84580
A38: 45156 | B38: =MONTH(A38) -> 8 | C38: =YEAR((A38)) -> 2023 | D38: Pago cliente | E38: Taller | F38: Fiori Martin | H38: Transferencia | J38: 57600
A39: 45156 | B39: =MONTH(A39) -> 8 | C39: =YEAR((A39)) -> 2023 | D39: Pago cliente | E39: Taller | F39: martina carlos | H39: Cheque de terceros | J39: 7000
A40: 45156 | B40: =MONTH(A40) -> 8 | C40: =YEAR((A40)) -> 2023 | D40: Pago cliente | E40: Taller | F40: martina carlos | H40: Cheque de terceros | J40: 6500
A41: 45160 | B41: =MONTH(A41) -> 8 | C41: =YEAR((A41)) -> 2023 | D41: Pago cliente | E41: Taller | F41: suarez lucas | H41: Transferencia | J41: 95200
...

Sheet Base Libro Caja
A2: FECHA | B2: MES | C2: AÑO | D2: CONCEPTO | E2: UNIDAD DE NEGOCIO | F2: DETALLE | G2: PROVEEDOR | J2: DEBE (INGRESO) | K2: HABER (EGRESO) | L2: SALDO DEUDOR | M2: SALDO ACREEDOR | N2: IVA | O2: FACTURADO A SAS | Q2: Concepto | R2: Unidad de negocio | S2: Proveedor
A3: 45132 | B3: =MONTH(A3) -> 7 | C3: =YEAR(A3) -> 2023 | D3: Saldo inicial | E3: Taller | F3: Pago con transferencia | J3: 3000 | L3: =3000+1950 -> 4950 | M3: 0 | Q3: Pago cliente | R3: Personal | S3: Barotto
A4: 45132 | B4: =MONTH(A4) -> 7 | C4: =YEAR(A4) -> 2023 | L4: =IF((L3+M3+J4-K4)>0,(L3+M3+J4-K4),0) -> 4950 | M4: =IF((L3+M3+J4-K4)<0,(L3+M3+J4-K4),0) -> 0 | Q4: Impuestos Municipales | R4: Taller | S4: Ferrando
A5: 45132 | B5: =MONTH(A5) -> 7 | C5: =YEAR(A5) -> 2023 | D5: Pago cliente | E5: Taller | F5: efectivo | J5: 60000 | L5: =IF((L4+M4+J5-K5)>0,(L4+M4+J5-K5),0) -> 64950 | M5: =IF((L4+M4+J5-K5)<0,(L4+M4+J5-K5),0) -> 0 | Q5: Saldo inicial | S5: Bata rio 4
A6: 45133 | B6: =MONTH(A6) -> 7 | C6: =YEAR(A6) -> 2023 | D6: Gastos generales | E6: Taller | F6: efectivo | K6: 5200 | L6: =IF((L5+M5+J6-K6)>0,(L5+M5+J6-K6),0) -> 59750 | M6: =IF((L5+M5+J6-K6)<0,(L5+M5+J6-K6),0) -> 0 | Q6: Pago cliente casual | S6: Vetaro
A7: 45133 | B7: =MONTH(A7) -> 7 | C7: =YEAR(A7) -> 2023 | D7: Ingreso a Caja chica | E7: Taller | F7: pago Cristian | J7: 64388.86 | L7: =IF((L6+M6+J7-K7)>0,(L6+M6+J7-K7),0) -> 124138.86 | M7: =IF((L6+M6+J7-K7)<0,(L6+M6+J7-K7),0) -> 0 | Q7: Librería | S7: Stabio
A8: 45133 | B8: =MONTH(A8) -> 7 | C8: =YEAR(A8) -> 2023 | D8: Pago proveedor | E8: Taller | F8: pago Cristian | G8: RC distribuciones | K8: 64388.86 | L8: =IF((L7+M7+J8-K8)>0,(L7+M7+J8-K8),0) -> 59750 | M8: =IF((L7+M7+J8-K8)<0,(L7+M7+J8-K8),0) -> 0 | Q8: Articulos de limpieza | S8: Accotto Aldo
A9: 45133 | B9: =MONTH(A9) -> 7 | C9: =YEAR(A9) -> 2023 | D9: Ingreso a Caja chica | E9: Taller | F9: pago Cristian | J9: 38631.07 | L9: =IF((L8+M8+J9-K9)>0,(L8+M8+J9-K9),0) -> 98381.07 | M9: =IF((L8+M8+J9-K9)<0,(L8+M8+J9-K9),0) -> 0 | Q9: Combustible | S9: Color Plus
A10: 45133 | B10: =MONTH(A10) -> 7 | C10: =YEAR(A10) -> 2023 | D10: Pago proveedor | E10: Taller | G10: Rep Center | K10: 38631.07 | L10: =IF((L9+M9+J10-K10)>0,(L9+M9+J10-K10),0) -> 59750 | M10: =IF((L9+M9+J10-K10)<0,(L9+M9+J10-K10),0) -> 0 | Q10: Ingreso a Caja grande | S10: Magliano Metal
A11: 45133 | B11: =MONTH(A11) -> 7 | C11: =YEAR(A11) -> 2023 | D11: Personal | E11: Personal | F11: Mutual Medic | K11: 2800 | L11: =IF((L10+M10+J11-K11)>0,(L10+M10+J11-K11),0) -> 56950 | M11: =IF((L10+M10+J11-K11)<0,(L10+M10+J11-K11),0) -> 0 | Q11: Ingreso a Caja chica | S11: Marglas S.A
A12: 45133 | B12: =MONTH(A12) -> 7 | C12: =YEAR(A12) -> 2023 | D12: Pago cliente | E12: Taller | J12: 8000 | L12: =IF((L11+M11+J12-K12)>0,(L11+M11+J12-K12),0) -> 64950 | M12: =IF((L11+M11+J12-K12)<0,(L11+M11+J12-K12),0) -> 0 | Q12: Pago proveedor | S12: Refiat
A13: 45133 | B13: =MONTH(A13) -> 7 | C13: =YEAR(A13) -> 2023 | D13: Vuelto cliente | E13: Taller | J13: 4500 | L13: =IF((L12+M12+J13-K13)>0,(L12+M12+J13-K13),0) -> 69450 | M13: =IF((L12+M12+J13-K13)<0,(L12+M12+J13-K13),0) -> 0 | Q13: Personal | S13: Rep Center
A14: 45133 | B14: =MONTH(A14) -> 7 | C14: =YEAR(A14) -> 2023 | D14: Ingreso a Caja grande | E14: Taller | F14: cierre caja | K14: 64500 | L14: =IF((L13+M13+J14-K14)>0,(L13+M13+J14-K14),0) -> 4950 | M14: =IF((L13+M13+J14-K14)<0,(L13+M13+J14-K14),0) -> 0 | Q14: Gastos generales | S14: RC distribuciones
A15: 45134 | B15: =MONTH(A15) -> 7 | C15: =YEAR(A15) -> 2023 | D15: Pago cliente | E15: Taller | J15: 25000 | L15: =IF((L14+M14+J15-K15)>0,(L14+M14+J15-K15),0) -> 29950 | M15: =IF((L14+M14+J15-K15)<0,(L14+M14+J15-K15),0) -> 0 | Q15: Comisiones | S15: Rectificadora Debernardi
A16: 45134 | B16: =MONTH(A16) -> 7 | C16: =YEAR(A16) -> 2023 | D16: Pago cliente | E16: Taller | J16: =49960+4340 -> 54300 | L16: =IF((L15+M15+J16-K16)>0,(L15+M15+J16-K16),0) -> 84250 | M16: =IF((L15+M15+J16-K16)<0,(L15+M15+J16-K16),0) -> 0 | Q16: Vuelto cliente | S16: TDI
A17: 45134 | B17: =MONTH(A17) -> 7 | C17: =YEAR(A17) -> 2023 | D17: Ingreso a Caja grande | E17: Taller | F17: 100 dolares | K17: 54300 | L17: =IF((L16+M16+J17-K17)>0,(L16+M16+J17-K17),0) -> 29950 | M17: =IF((L16+M16+J17-K17)<0,(L16+M16+J17-K17),0) -> 0 | Q17: Servicios | S17: Forcor
A18: 45134 | B18: =MONTH(A18) -> 7 | C18: =YEAR(A18) -> 2023 | D18: Pago cliente | E18: Taller | F18: vuelto | K18: 4340 | L18: =IF((L17+M17+J18-K18)>0,(L17+M17+J18-K18),0) -> 25610 | M18: =IF((L17+M17+J18-K18)<0,(L17+M17+J18-K18),0) -> 0 | Q18: Sueldos | S18: Shell Bata
A19: 45134 | B19: =MONTH(A19) -> 7 | C19: =YEAR(A19) -> 2023 | D19: Ingreso a Caja chica | E19: Taller | F19: caja grande | J19: 25000 | L19: =IF((L18+M18+J19-K19)>0,(L18+M18+J19-K19),0) -> 50610 | M19: =IF((L18+M18+J19-K19)<0,(L18+M18+J19-K19),0) -> 0 | Q19: Honorarios | S19: Mundo Chevrolet
A20: 45134 | B20: =MONTH(A20) -> 7 | C20: =YEAR(A20) -> 2023 | D20: Gastos generales | E20: Taller | F20: leña | K20: 25000 | L20: =IF((L19+M19+J20-K20)>0,(L19+M19+J20-K20),0) -> 25610 | M20: =IF((L19+M19+J20-K20)<0,(L19+M19+J20-K20),0) -> 0 | Q20: Sueldo administrativo | S20: Alarmas
A21: 45134 | B21: =MONTH(A21) -> 7 | C21: =YEAR(A21) -> 2023 | D21: Ingreso a Caja chica | E21: Taller | F21: caja grande | J21: 2000 | L21: =IF((L20+M20+J21-K21)>0,(L20+M20+J21-K21),0) -> 27610 | M21: =IF((L20+M20+J21-K21)<0,(L20+M20+J21-K21),0) -> 0 | Q21: Sueldo mecánicos | S21: Atilio Lucero
A22: 45134 | B22: =MONTH(A22) -> 7 | C22: =YEAR(A22) -> 2023 | D22: Personal | E22: Personal | F22: analisis | K22: 1380 | L22: =IF((L21+M21+J22-K22)>0,(L21+M21+J22-K22),0) -> 26230 | M22: =IF((L21+M21+J22-K22)<0,(L21+M21+J22-K22),0) -> 0 | Q22: Herramientas / bienes de uso | S22: Rio Rep
A23: 45134 | B23: =MONTH(A23) -> 7 | C23: =YEAR(A23) -> 2023 | D23: Comisiones | E23: Taller | F23: comisionista | K23: 2000 | L23: =IF((L22+M22+J23-K23)>0,(L22+M22+J23-K23),0) -> 24230 | M23: =IF((L22+M22+J23-K23)<0,(L22+M22+J23-K23),0) -> 0 | Q23: Servicios de terceros | S23: Sabaini Ignacio
A24: 45134 | B24: =MONTH(A24) -> 7 | C24: =YEAR(A24) -> 2023 | D24: Ingreso a Caja grande | E24: Taller | F24: cierre caja | K24: =22280-3000 -> 19280 | L24: =IF((L23+M23+J24-K24)>0,(L23+M23+J24-K24),0) -> 4950 | M24: =IF((L23+M23+J24-K24)<0,(L23+M23+J24-K24),0) -> 0 | Q24: Calcomanias | S24: Rolando Juan
A25: 45135 | B25: =MONTH(A25) -> 7 | C25: =YEAR(A25) -> 2023 | D25: Ingreso a Caja chica | E25: Taller | J25: 19200 | L25: =IF((L24+M24+J25-K25)>0,(L24+M24+J25-K25),0) -> 24150 | M25: =IF((L24+M24+J25-K25)<0,(L24+M24+J25-K25),0) -> 0 | Q25: Monotributo | S25: Bertea
A26: 45135 | B26: =MONTH(A26) -> 7 | C26: =YEAR(A26) -> 2023 | D26: Pago proveedor | E26: Taller | G26: Ferrando | K26: 19280 | L26: =IF((L25+M25+J26-K26)>0,(L25+M25+J26-K26),0) -> 4870 | M26: =IF((L25+M25+J26-K26)<0,(L25+M25+J26-K26),0) -> 0 | Q26: Publicidad | S26: Chemical
A27: 45135 | B27: =MONTH(A27) -> 7 | C27: =YEAR(A27) -> 2023 | D27: Ingreso a Caja chica | E27: Taller | J27: 25000 | L27: =IF((L26+M26+J27-K27)>0,(L26+M26+J27-K27),0) -> 29870 | M27: =IF((L26+M26+J27-K27)<0,(L26+M26+J27-K27),0) -> 0 | Q27: Ropa | S27: Mansilla
A28: 45135 | B28: =MONTH(A28) -> 7 | C28: =YEAR(A28) -> 2023 | D28: Gastos generales | E28: Taller | F28: leña | K28: 25000 | L28: =IF((L27+M27+J28-K28)>0,(L27+M27+J28-K28),0) -> 4870 | M28: =IF((L27+M27+J28-K28)<0,(L27+M27+J28-K28),0) -> 0 | Q28: Impuestos AFIP | S28: Pablo Fenoglio
A29: 45135 | B29: =MONTH(A29) -> 7 | C29: =YEAR(A29) -> 2023 | D29: Ingreso a Caja chica | E29: Personal | J29: 22500 | L29: =IF((L28+M28+J29-K29)>0,(L28+M28+J29-K29),0) -> 27370 | M29: =IF((L28+M28+J29-K29)<0,(L28+M28+J29-K29),0) -> 0 | S29: Sthil Gutierrez
A30: 45135 | B30: =MONTH(A30) -> 7 | C30: =YEAR(A30) -> 2023 | D30: Personal | E30: Personal | F30: fumigador | K30: 22500 | L30: =IF((L29+M29+J30-K30)>0,(L29+M29+J30-K30),0) -> 4870 | M30: =IF((L29+M29+J30-K30)<0,(L29+M29+J30-K30),0) -> 0
A31: 45135 | B31: =MONTH(A31) -> 7 | C31: =YEAR(A31) -> 2023 | D31: Ingreso a Caja chica | E31: Taller | J31: 2600 | L31: =IF((L30+M30+J31-K31)>0,(L30+M30+J31-K31),0) -> 7470 | M31: =IF((L30+M30+J31-K31)<0,(L30+M30+J31-K31),0) -> 0
A32: 45135 | B32: =MONTH(A32) -> 7 | C32: =YEAR(A32) -> 2023 | D32: Gastos generales | E32: Taller | F32: gas | K32: 2600 | L32: =IF((L31+M31+J32-K32)>0,(L31+M31+J32-K32),0) -> 4870 | M32: =IF((L31+M31+J32-K32)<0,(L31+M31+J32-K32),0) -> 0
A33: 45135 | B33: =MONTH(A33) -> 7 | C33: =YEAR(A33) -> 2023 | D33: Pago cliente | E33: Taller | F33: Service Palloni | J33: 4500 | L33: =IF((L32+M32+J33-K33)>0,(L32+M32+J33-K33),0) -> 9370 | M33: =IF((L32+M32+J33-K33)<0,(L32+M32+J33-K33),0) -> 0
A34: 45135 | B34: =MONTH(A34) -> 7 | C34: =YEAR(A34) -> 2023 | D34: Pago cliente | E34: Taller | J34: 223820 | L34: =IF((L33+M33+J34-K34)>0,(L33+M33+J34-K34),0) -> 233190 | M34: =IF((L33+M33+J34-K34)<0,(L33+M33+J34-K34),0) -> 0
A35: 45135 | B35: =MONTH(A35) -> 7 | C35: =YEAR(A35) -> 2023 | D35: Ingreso a Caja grande | E35: Taller | F35: cierre caja | K35: 230190 | L35: =IF((L34+M34+J35-K35)>0,(L34+M34+J35-K35),0) -> 3000 | M35: =IF((L34+M34+J35-K35)<0,(L34+M34+J35-K35),0) -> 0
A36: 45136 | B36: =MONTH(A36) -> 7 | C36: =YEAR(A36) -> 2023 | D36: Pago cliente casual | E36: Taller | J36: 3000 | L36: =IF((L35+M35+J36-K36)>0,(L35+M35+J36-K36),0) -> 6000 | M36: =IF((L35+M35+J36-K36)<0,(L35+M35+J36-K36),0) -> 0
A37: 45136 | B37: =MONTH(A37) -> 7 | C37: =YEAR(A37) -> 2023 | D37: Gastos generales | E37: Taller | F37: publicidad web | K37: 3000 | L37: =IF((L36+M36+J37-K37)>0,(L36+M36+J37-K37),0) -> 3000 | M37: =IF((L36+M36+J37-K37)<0,(L36+M36+J37-K37),0) -> 0
A38: 45136 | B38: =MONTH(A38) -> 7 | C38: =YEAR(A38) -> 2023 | D38: Pago cliente | E38: Taller | J38: 70000 | L38: =IF((L37+M37+J38-K38)>0,(L37+M37+J38-K38),0) -> 73000 | M38: =IF((L37+M37+J38-K38)<0,(L37+M37+J38-K38),0) -> 0
A39: 45136 | B39: =MONTH(A39) -> 7 | C39: =YEAR(A39) -> 2023 | D39: Ingreso a Caja grande | E39: Taller | K39: 70000 | L39: =IF((L38+M38+J39-K39)>0,(L38+M38+J39-K39),0) -> 3000 | M39: =IF((L38+M38+J39-K39)<0,(L38+M38+J39-K39),0) -> 0
A40: 45138 | B40: =MONTH(A40) -> 7 | C40: =YEAR(A40) -> 2023 | D40: Pago cliente | E40: Taller | J40: 86850 | L40: =IF((L39+M39+J40-K40)>0,(L39+M39+J40-K40),0) -> 89850 | M40: =IF((L39+M39+J40-K40)<0,(L39+M39+J40-K40),0) -> 0
A41: 45138 | B41: =MONTH(A41) -> 7 | C41: =YEAR(A41) -> 2023 | D41: Pago cliente | E41: Taller | J41: 70000 | L41: =IF((L40+M40+J41-K41)>0,(L40+M40+J41-K41),0) -> 159850 | M41: =IF((L40+M40+J41-K41)<0,(L40+M40+J41-K41),0) -> 0
...

Sheet G. personales
A2: UNIDAD DE NEGOCIO | B2: Personal
A3: AÑO | B3: (Varios elementos)
A5: Etiquetas de fila | B5: Suma de HABER (EGRESO)
A6: 9 | B6: 4034580
A7: 8 | B7: 5330103.4
A8: 10 | B8: 5431354.7
A9: 11 | B9: 4648613.7
A10: 1 | B10: 2703737.3
A11: 2 | B11: 1363366.4
A12: 3 | B12: 2019494.7
A13: 4 | B13: 2283356.5
A14: 5 | B14: 1623467.8
A15: 6 | B15: 2329229.6
A16: 7 | B16: 3337950.8
A17: Total general | B17: 35105255

Sheet Indic 2019
A3: Sale | B3: Contabilidad | E3: =2400000/12 -> 200000
A5: Rótulos de fila | B5: Suma de Total 19
A6: Egreso | B6: 2387026.8 | C6: % total Egr | D6: % total Ing | G6: 0.082 | H6: 1.2 | I6: Debito/credito | J6: 0.85
A7: Bancario | B7: 452108.35 | C7: =B7/$B$6 -> 0.1894023 | D7: =B7/$B$16 -> 0.16003946 | H7: 2.26 | I7: Funcionamiento general
A8: Comisiones | B8: 92120 | C8: =B8/$B$6 -> 0.038591943 | D8: =B8/$B$16 -> 0.032609074 | H8: 0.34 | I8: Ing brutos
A9: Funcionamiento | B9: 82164.97 | C9: =B9/$B$6 -> 0.03442147 | D9: =B9/$B$16 -> 0.029085145 | H9: 3.9 | I9: Sueldos
A10: Honorarios | B10: 330039.09 | C10: =B10/$B$6 -> 0.13826367 | D10: =B10/$B$16 -> 0.1168288 | H10: 0.3 | I10: Gastos bancarios
A11: Impuestos y servicios | B11: 122288.53 | C11: =B11/$B$6 -> 0.051230481 | D11: =B11/$B$16 -> 0.043288273 | G11: 0.016 | H11: 0.9 | I11: Plazo fijo | J11: 0.15
A12: Ingresos brutos | B12: 101008.74 | C12: =B12/$B$6 -> 0.042315713 | D12: =B12/$B$16 -> 0.035755552 | H12: 0.6 | I12: Sobrante
A13: Limpieza | B13: 13300 | C13: =B13/$B$6 -> 0.005571785 | D13: =B13/$B$16 -> 0.004707997
A14: Papeleria | B14: 38790.92 | C14: =B14/$B$6 -> 0.016250727 | D14: =B14/$B$16 -> 0.013731394
A15: Sueldos | B15: 1155206.2 | C15: =B15/$B$6 -> 0.48395191 | D15: =B15/$B$16 -> 0.40892535 | G15: El total de ingresos podemos decir que es un 9,8 % de la liquidación. El 85% , que equivale a 8,2 puntos se utiliza para pagar gastos de funcionamiento de la estructura y 15% que equivale al 1,6 se utiliza para "ahorro". 1 punto aproximadamente hoy es lo que se tiene en plazo fijo. Con estos datos vemos que lo que se podría reducir es 1 punto en general que sería el 0,6 de sobrante + 0,34 de ingresos brutos que descontaba Osde y ya no lo descuenta más.
A16: Ingreso | B16: 2824980.5
A17: Alquiler | B17: 94800 | C17: =B17/$B$16 -> 0.033557753
A18: Cuota Colegio | B18: 441059 | C18: =B18/$B$16 -> 0.15612815
A19: Gtos adm Colegio Médico | B19: 2289121.5 | C19: =B19/$B$16 -> 0.81031409
A20: Total general | B20: 5212007.3
C24: 2300000 | D24: 8 | G24: Galvez - Propall plantea abonar al Colegio Médico un 3% sobre facturación. Los servicios que si o si debería abonar son 2,26 de funcionamiento general + 0,3 de gastos bancarios . realizar la parte operativa de facturación y liquidación en sus oficinas propias y utilizar el servicio de negociación de aranceles y gestión de pagos del Colegio Médico. También que la OS abone las facturas directamente a Propall para evitar el 1,2 de débito/crédito y abonar en lugar
C25: 95000 | D25: =C25*D24/C24 -> 0.33043478 | E25: 1.5
E26: 0.33
A28: FIESTA DÍA DEL MÉDICO 2019
A30: CONCEPTO | B30: ENTRADA | C30: SALIDA
A31: Tarjeta socio | B31: 87000
A32: Hotel colonial menu | C32: 82500
A33: Música carranza mauro | C33: 7000
A34: Muñiz musica | C34: 6000
A35: Cotillon cotimundo | C35: 1550
A36: Mercado libre copa copon cristal | C36: 12599.93
A37: Mercado libre cotillon | C37: 2204
A38: Mercado libre minipimer | C38: 6396
A39: Mercado libre plancha vapor | C39: 9897.36
A40: Mercado libre secador pelo | C40: 8394
A41: Camoati moños y bolsas regalos cena medico | C41: 1023.07
A42: Arredo regalos cena medicos | C42: 18053.2
A43: TOTAL | B43: =SUM(B31:B42) -> 87000 | C43: =SUM(C31:C42) -> 155617.56
A44: RESULTADO | B44: =B43-C43 -> -68617.56
B54: Valores
A55: Egresos | B55: Enero | C55: Febrero | D55: Marzo | E55: Abril | F55: Mayo
A56: Bancario | B56: 55283.44 | C56: 48533.96 | D56: 40335.89 | E56: 43719.99 | F56: 48791.16
A57: Comisiones | B57: 11600 | C57: 5200.02 | D57: 9030.01 | E57: 12090.02 | F57: 8070.02
...

Sheet Resumen 2020
A1: Concepto | B1: Detalle | C1: Moviemieto | D1: 1 | E1: 2 | F1: 3 | G1: 4 | H1: 5 | I1: 6
A2: Sueldos | B2: Sueldos | C2: Egreso | D2: 69368.32 | E2: 108847.36 | F2: 139394.1 | G2: 74097.12 | H2: 77205.39
A3: Sueldos | B3: Pago electrónico de aportes y cargas sociales | C3: Egreso | E3: 105557.22 | F3: 56524.11 | G3: 29259.37 | H3: 68817.69
A4: Bancario | B4: Impuesto débito/crédito | C4: Egreso | D4: 38484.97 | E4: 32276.01 | F4: 32543.08 | G4: 35102.71 | H4: 39779.21
A5: Honorarios | B5: Honorarios | C5: Egreso | D5: 35000 | E5: 30000 | F5: 30000 | G5: 30000 | H5: 30000
A6: Funcionamiento | B6: Gastos varios caja chica | C6: Egreso | D6: 10000 | E6: 2350 | F6: 3200
A7: Impuestos y servicios | B7: Pago electrónico Impuestos | C7: Egreso | D7: 3319.46 | E7: 10591.32 | F7: 8856.69 | G7: 10941.22 | H7: 7567.06
A8: Bancario | B8: Comisión canje Bp | C8: Egreso | D8: 11992.99 | E8: 11648.26 | F8: 4821.85 | G8: 5285.87 | H8: 5543.06
A9: Comisiones | B9: Comisionistas | C9: Egreso | D9: 7550 | E9: 300 | F9: 6300 | G9: 7600 | H9: 4900
A10: Funcionamiento | B10: Mantenimiento VCL | C10: Egreso | D10: 16335.03 | E10: 1500
A11: Bancario | B11: IVA 21% comisiones | C11: Egreso | D11: 2915.48 | E11: 2719.69 | F11: 1080.96 | G11: 1441.41 | H11: 1578.89
A12: Bancario | B12: Gastos mantenimiento /comisiones varias | C12: Egreso | D12: 1890 | E12: 1890 | F12: 1890 | G12: 1890 | H12: 1890
A13: Papelería | B13: Librería | C13: Egreso | D13: 3999.86 | F13: 3736.23
A14: Funcionamiento | B14: Publicidad | C14: Egreso | E14: 800
A15: Bancario | B15: cheque anulado | C15: Egreso | F15: 0
A16: Comisiones | B16: Gasto franqueo | C16: Egreso | D16: 4050 | E16: 4900.02 | F16: 1940.01 | G16: 4490.02 | H16: 3170.02 | I16: 4240.01
A17: Impuestos y servicios | B17: Impuestos y servicios | C17: Egreso | D17: 9602.13 | F17: 1816.41 | H17: 4018.67 | I17: 1318.28
A18: Funcionamiento | B18: Gastos Varios | C18: Egreso | D18: 1520 | E18: 2802 | F18: 2119.47 | G18: 1229 | H18: 2410.65 | I18: 2593.2
A19: Limpieza | B19: Servicio de limpieza | C19: Egreso | D19: 1200 | E19: 1200 | F19: 600 | G19: 1200 | H19: 1380 | I19: 1200
A20: Funcionamiento | B20: Gasto administrativo alquiler Rotary | C20: Egreso | D20: 800 | E20: 800 | F20: 800 | G20: 800 | H20: 800 | I20: 800
A21: Funcionamiento | B21: Supermercado | C21: Egreso | D21: 944.6 | E21: 546.8 | F21: 1374.2
A22: Funcionamiento | B22: Gastos de mantenimiento | C22: Egreso | E22: 1164 | I22: 500
A23: Funcionamiento | B23: Reuniones | C23: Egreso | G23: 800
A24: Comisiones | B24: Certificación de firma | C24: Egreso | F24: 790
A25: Papelería | B25: Librería | C25: Egreso | H25: 644.5
A26: Limpieza | B26: Insumos limpieza | C26: Egreso | H26: 370.8
A27: Papelería | B27: Imprenta | C27: Egreso | D27: 340
