Workbook

Sheet Carga Presup.
D2: PRESUPUESTOS
A3: Nro comp. | B3: contador | C3: Fecha | D3: Cliente | F3: Dominio | G3: Vehículo | H3: Diagnóstico | J3: Código | K3: Repuesto | L3: Proveedor | M3: Costo | N3: Comisionista | O3: % ganancia | P3: Cantidad | Q3: Precio repuesto | R3: Total | S3: MO tiempo | T3: MO precio | U3: MO | V3: MO Acumulado
A4: 9 | B4: 1 | C4: 45131 | D4: Saturnino Santa Cruz | E4: =CONCATENATE(A4,D4,B4) -> 9Saturnino Santa Cruz1 | G4: Voyage | H4: Service y Distribución. | I4: =H4 -> Service y Distribución. | K4: Aceite motor | P4: 1 | Q4: 22000 | R4: =Q4*P4 -> 22000 | S4: 1 | T4: 60000 | U4: =+T4*S4 -> 60000 | V4: =U4 -> 60000
A5: 10 | B5: =IF(A5=A4,B4+1,1) -> 1 | C5: =IF(A5=A4,C4,"") | D5: =IF(A5=A4,D4,"") | E5: =CONCATENATE(A5,D5,B5) -> 101 | I5: =IF(A5=A4,CONCATENATE(I4," ",H5),H5) -> 0 | K5: Filtros | P5: 1 | Q5: 14520 | R5: =Q5*P5 -> 14520 | U5: =+T5*S5 -> 0 | V5: =IF(A5=A4,V4+U5,U5) -> 0
A6: 10 | B6: =IF(A6=A5,B5+1,1) -> 2 | C6: =IF(A6=A5,C5,"") | D6: =IF(A6=A5,D5,"") | E6: =CONCATENATE(A6,D6,B6) -> 102 | I6: =IF(A6=A5,CONCATENATE(I5," ",H6),H6) -> 0 | K6: Kit distribución | P6: 1 | Q6: 63800 | R6: =Q6*P6 -> 63800 | U6: =+T6*S6 -> 0 | V6: =IF(A6=A5,V5+U6,U6) -> 0
A7: 10 | B7: =IF(A7=A6,B6+1,1) -> 3 | C7: =IF(A7=A6,C6,"") | D7: =IF(A7=A6,D6,"") | E7: =CONCATENATE(A7,D7,B7) -> 103 | I7: =IF(A7=A6,CONCATENATE(I6," ",H7),H7) -> 0 | K7: Refrigerante + Destilada | P7: 1 | Q7: 7000 | R7: =Q7*P7 -> 7000 | U7: =+T7*S7 -> 0 | V7: =IF(A7=A6,V6+U7,U7) -> 0
A8: 11 | B8: =IF(A8=A7,B7+1,1) -> 1 | C8: 45132 | D8: OCA LOG S.A | E8: =CONCATENATE(A8,D8,B8) -> 11OCA LOG S.A1 | F8: 297 | G8: Ford Ranger | H8: Limpieza circuito refrigeración. | I8: =IF(A8=A7,CONCATENATE(I7," ",H8),H8) -> Limpieza circuito refrigeración. | K8: Liquido desincrustante | P8: 1 | Q8: 4000 | R8: =Q8*P8 -> 4000 | U8: =+T8*S8 -> 0 | V8: =IF(A8=A7,V7+U8,U8) -> 0
A9: 11 | B9: =IF(A9=A8,B8+1,1) -> 2 | C9: =IF(A9=A8,C8,"") -> 45132 | D9: =IF(A9=A8,D8,"") -> OCA LOG S.A | E9: =CONCATENATE(A9,D9,B9) -> 11OCA LOG S.A2 | H9: Cambio refrigerante y purgado del circuito. | I9: =IF(A9=A8,CONCATENATE(I8," ",H9),H9) -> Limpieza circuito refrigeración. Cambio refrigerante y purgado del circuito. | K9: Liquido refrigerante + destilada | P9: 1 | Q9: 7000 | R9: =Q9*P9 -> 7000 | S9: 1 | T9: 10000 | U9: =+T9*S9 -> 10000 | V9: =IF(A9=A8,V8+U9,U9) -> 10000
A10: 11 | B10: =IF(A10=A9,B9+1,1) -> 3 | C10: =IF(A10=A9,C9,"") -> 45132 | D10: =IF(A10=A9,D9,"") -> OCA LOG S.A | E10: =CONCATENATE(A10,D10,B10) -> 11OCA LOG S.A3 | H10: Lavado interior del block. | I10: =IF(A10=A9,CONCATENATE(I9," ",H10),H10) -> Limpieza circuito refrigeración. Cambio refrigerante y purgado del circuito. Lavado interior del block. | R10: =Q10*P10 -> 0 | U10: =+T10*S10 -> 0 | V10: =IF(A10=A9,V9+U10,U10) -> 10000
A11: 12 | B11: =IF(A11=A10,B10+1,1) -> 1 | C11: 45133 | D11: Bastianelli | E11: =CONCATENATE(A11,D11,B11) -> 12Bastianelli1 | G11: Peugeot 206 | H11: Cambiar kit de distribución. | I11: =IF(A11=A10,CONCATENATE(I10," ",H11),H11) -> Cambiar kit de distribución. | K11: Kit distribución | P11: 1 | Q11: 28000 | R11: =Q11*P11 -> 28000 | U11: =+T11*S11 -> 0 | V11: =IF(A11=A10,V10+U11,U11) -> 0
A12: 12 | B12: =IF(A12=A11,B11+1,1) -> 2 | C12: =IF(A12=A11,C11,"") -> 45133 | D12: =IF(A12=A11,D11,"") -> Bastianelli | E12: =CONCATENATE(A12,D12,B12) -> 12Bastianelli2 | H12: Cambiar correa poliv. | I12: =IF(A12=A11,CONCATENATE(I11," ",H12),H12) -> Cambiar kit de distribución. Cambiar correa poliv. | K12: Correa poliv | P12: 1 | Q12: 9000 | R12: =Q12*P12 -> 9000 | U12: =+T12*S12 -> 0 | V12: =IF(A12=A11,V11+U12,U12) -> 0
A13: 12 | B13: =IF(A13=A12,B12+1,1) -> 3 | C13: =IF(A13=A12,C12,"") -> 45133 | D13: =IF(A13=A12,D12,"") -> Bastianelli | E13: =CONCATENATE(A13,D13,B13) -> 12Bastianelli3 | H13: Cambiar bomba de agua. | I13: =IF(A13=A12,CONCATENATE(I12," ",H13),H13) -> Cambiar kit de distribución. Cambiar correa poliv. Cambiar bomba de agua. | K13: Bomba de agua | P13: 1 | Q13: 15800 | R13: =Q13*P13 -> 15800 | U13: =+T13*S13 -> 0 | V13: =IF(A13=A12,V12+U13,U13) -> 0
A14: 12 | B14: =IF(A14=A13,B13+1,1) -> 4 | C14: =IF(A14=A13,C13,"") -> 45133 | D14: =IF(A14=A13,D13,"") -> Bastianelli | E14: =CONCATENATE(A14,D14,B14) -> 12Bastianelli4 | I14: =IF(A14=A13,CONCATENATE(I13," ",H14),H14) -> Cambiar kit de distribución. Cambiar correa poliv. Cambiar bomba de agua. | K14: Liquido refrigerante + | P14: 1 | Q14: 7000 | R14: =Q14*P14 -> 7000 | S14: 1 | T14: 38000 | U14: =+T14*S14 -> 38000 | V14: =IF(A14=A13,V13+U14,U14) -> 38000
A15: 12 | B15: =IF(A15=A14,B14+1,1) -> 5 | C15: =IF(A15=A14,C14,"") -> 45133 | D15: =IF(A15=A14,D14,"") -> Bastianelli | E15: =CONCATENATE(A15,D15,B15) -> 12Bastianelli5 | I15: =IF(A15=A14,CONCATENATE(I14," ",H15),H15) -> Cambiar kit de distribución. Cambiar correa poliv. Cambiar bomba de agua. | K15: agua destilada. | R15: =Q15*P15 -> 0 | U15: =+T15*S15 -> 0 | V15: =IF(A15=A14,V14+U15,U15) -> 38000
A16: 13 | B16: =IF(A16=A15,B15+1,1) -> 1 | C16: 45139 | D16: OCA LOG S.A | E16: =CONCATENATE(A18,D16,B16) -> 13OCA LOG S.A1 | F16: 297 | G16: Ford Ranger | H16: Sacar turbo multiple de escape. | I16: =IF(A18=A15,CONCATENATE(I15," ",H16),H16) -> Sacar turbo multiple de escape. | R16: =Q16*P16 -> 0 | S16: 1 | T16: 35000 | U16: =+T16*S16 -> 35000 | V16: =IF(A18=A15,V15+U16,U16) -> 35000
A17: 13 | B17: =IF(A17=A16,B16+1,1) -> 2 | C17: 45139 | D17: OCA LOG S.A | E17: =CONCATENATE(A17,D17,B17) -> 13OCA LOG S.A2 | H17: Cambiar tapones de block lado izquierdo. Armado total. | I17: =IF(A17=A18,CONCATENATE(I16," ",H17),H17) -> Sacar turbo multiple de escape. Cambiar tapones de block lado izquierdo. Armado total. | R17: =Q17*P17 -> 0 | U17: =+T17*S17 -> 0 | V17: =IF(A17=A18,V16+U17,U17) -> 35000
A18: 13 | B18: =IF(A18=A17,B17+1,1) -> 3 | C18: 45139 | D18: OCA LOG S.A | E18: =CONCATENATE(A18,D18,B18) -> 13OCA LOG S.A3 | I18: =IF(#REF!=A17,CONCATENATE(I17," ",H18),H18) -> #REF! | R18: =Q18*P18 -> 0 | U18: =+T18*S18 -> 0 | V18: =IF(#REF!=A17,V17+U18,U18) -> #REF!
A19: 14 | B19: =IF(A19=A18,B18+1,1) -> 1 | C19: 45140 | D19: Moreno Orlando | E19: =CONCATENATE(A19,D19,B19) -> 14Moreno Orlando1 | G19: Amarok | H19: Cambiar kit distribución con bomba de agua. | I19: =IF(A19=#REF!,CONCATENATE(I18," ",H19),H19) -> #REF! | K19: Kit distribución con bomba de agua. | P19: 1 | Q19: 170000 | R19: =Q19*P19 -> 170000 | S19: 1 | T19: 40000 | U19: =+T19*S19 -> 40000 | V19: =IF(A19=#REF!,V18+U19,U19) -> #REF!
A20: 14 | B20: =IF(A20=A19,B19+1,1) -> 2 | C20: =IF(A20=A19,C19,"") -> 45140 | D20: =IF(A20=A19,D19,"") -> Moreno Orlando | E20: =CONCATENATE(A20,D20,B20) -> 14Moreno Orlando2 | H20: con polea de dirección hidraulica y correa poliv. | I20: =IF(A20=A19,CONCATENATE(I19," ",H20),H20) -> #REF! | K20: Polea de dirección hidráulica. | P20: 1 | Q20: 8000 | R20: =Q20*P20 -> 8000 | U20: =+T20*S20 -> 0 | V20: =IF(A20=A19,V19+U20,U20) -> #REF!
A21: 14 | B21: =IF(A21=A20,B20+1,1) -> 3 | C21: =IF(A21=A20,C20,"") -> 45140 | D21: =IF(A21=A20,D20,"") -> Moreno Orlando | E21: =CONCATENATE(A21,D21,B21) -> 14Moreno Orlando3 | I21: =IF(A21=A20,CONCATENATE(I20," ",H21),H21) -> #REF! | K21: Correa poliv. | P21: 1 | Q21: 9800 | R21: =Q21*P21 -> 9800 | U21: =+T21*S21 -> 0 | V21: =IF(A21=A20,V20+U21,U21) -> #REF!
A22: 14 | B22: =IF(A22=A21,B21+1,1) -> 4 | C22: =IF(A22=A21,C21,"") -> 45140 | D22: =IF(A22=A21,D21,"") -> Moreno Orlando | E22: =CONCATENATE(A22,D22,B22) -> 14Moreno Orlando4 | H22: Service cambio de aceite y filtros. | I22: =IF(A22=A21,CONCATENATE(I21," ",H22),H22) -> #REF! | K22: Aceite motor 5w30. | P22: 6 | Q22: 6500 | R22: =Q22*P22 -> 39000 | S22: 1 | T22: 30000 | U22: =+T22*S22 -> 30000 | V22: =IF(A22=A21,V21+U22,U22) -> #REF!
A23: 14 | B23: =IF(A23=A22,B22+1,1) -> 5 | C23: =IF(A23=A22,C22,"") -> 45140 | D23: =IF(A23=A22,D22,"") -> Moreno Orlando | E23: =CONCATENATE(A23,D23,B23) -> 14Moreno Orlando5 | I23: =IF(A23=A22,CONCATENATE(I22," ",H23),H23) -> #REF! | K23: Kit de filtros. | P23: 1 | Q23: 39000 | R23: =Q23*P23 -> 39000 | U23: =+T23*S23 -> 0 | V23: =IF(A23=A22,V22+U23,U23) -> #REF!
A24: 15 | B24: =IF(A24=A23,B23+1,1) -> 1 | C24: 45140 | D24: Beriani Nazarena | E24: =CONCATENATE(A24,D24,B24) -> 15Beriani Nazarena1 | G24: Kangoo | H24: Reparar eje trasero y engrasar | I24: =IF(A24=A23,CONCATENATE(I23," ",H24),H24) -> Reparar eje trasero y engrasar | K24: Juego de orring eje trasero | P24: 1 | Q24: 9800 | R24: =Q24*P24 -> 9800 | S24: 1 | T24: 35000 | U24: =+T24*S24 -> 35000 | V24: =IF(A24=A23,V23+U24,U24) -> 35000
A25: 16 | B25: =IF(A25=A24,B24+1,1) -> 1 | C25: 45140 | D25: Moreno Orlando | E25: =CONCATENATE(A25,D25,B25) -> 16Moreno Orlando1 | G25: Amarok | H25: Cambiar kit distribución con bomba de agua. | I25: =IF(A25=A24,CONCATENATE(I24," ",H25),H25) -> Cambiar kit distribución con bomba de agua. | K25: Kit distribución con bomba de agua. | P25: 1 | Q25: 170000 | R25: =Q25*P25 -> 170000 | S25: 1 | T25: 40000 | U25: =+T25*S25 -> 40000 | V25: =IF(A25=A24,V24+U25,U25) -> 40000
A26: 16 | B26: =IF(A26=A25,B25+1,1) -> 2 | C26: =IF(A26=A25,C25,"") -> 45140 | D26: =IF(A26=A25,D25,"") -> Moreno Orlando | E26: =CONCATENATE(A26,D26,B26) -> 16Moreno Orlando2 | H26: Polea de dirección hidráulica y correa poliv. | I26: =IF(A26=A25,CONCATENATE(I25," ",H26),H26) -> Cambiar kit distribución con bomba de agua. Polea de dirección hidráulica y correa poliv. | K26: Polea de dirección hidraulica | P26: 1 | Q26: 8200 | R26: =Q26*P26 -> 8200 | U26: =+T26*S26 -> 0 | V26: =IF(A26=A25,V25+U26,U26) -> 40000
A27: 16 | B27: =IF(A27=A26,B26+1,1) -> 3 | C27: =IF(A27=A26,C26,"") -> 45140 | D27: =IF(A27=A26,D26,"") -> Moreno Orlando | E27: =CONCATENATE(A27,D27,B27) -> 16Moreno Orlando3 | I27: =IF(A27=A26,CONCATENATE(I26," ",H27),H27) -> Cambiar kit distribución con bomba de agua. Polea de dirección hidráulica y correa poliv. | K27: Correa poliv. | P27: 1 | Q27: 9800 | R27: =Q27*P27 -> 9800 | U27: =+T27*S27 -> 0 | V27: =IF(A27=A26,V26+U27,U27) -> 40000
A28: 16 | B28: =IF(A28=A27,B27+1,1) -> 4 | C28: =IF(A28=A27,C27,"") -> 45140 | D28: =IF(A28=A27,D27,"") -> Moreno Orlando | E28: =CONCATENATE(A28,D28,B28) -> 16Moreno Orlando4 | I28: =IF(A28=A27,CONCATENATE(I27," ",H28),H28) -> Cambiar kit distribución con bomba de agua. Polea de dirección hidráulica y correa poliv. | U28: =+T28*S28 -> 0 | V28: =IF(A28=A27,V27+U28,U28) -> 40000
A29: 16 | B29: =IF(A29=A28,B28+1,1) -> 5 | C29: =IF(A29=A28,C28,"") -> 45140 | D29: =IF(A29=A28,D28,"") -> Moreno Orlando | E29: =CONCATENATE(A29,D29,B29) -> 16Moreno Orlando5 | I29: =IF(A29=A28,CONCATENATE(I28," ",H29),H29) -> Cambiar kit distribución con bomba de agua. Polea de dirección hidráulica y correa poliv. | U29: =+T29*S29 -> 0 | V29: =IF(A29=A28,V28+U29,U29) -> 40000
A30: 17 | B30: =IF(A30=A29,B29+1,1) -> 1 | C30: 45140 | D30: 8925 | E30: =CONCATENATE(A30,D30,B30) -> 1789251 | G30: Amarok | H30: Service cambio de aceite y filtros. | I30: =IF(A30=A29,CONCATENATE(I29," ",H30),H30) -> Service cambio de aceite y filtros. | K30: Aceite motor 5w30 | P30: 6 | Q30: 6500 | R30: =Q30*P30 -> 39000 | U30: =+T30*S30 -> 0 | V30: =IF(A30=A29,V29+U30,U30) -> 0
A31: 17 | B31: =IF(A31=A30,B30+1,1) -> 2 | C31: =IF(A31=A30,C30,"") -> 45140 | D31: =IF(A31=A30,D30,"") -> 8925 | E31: =CONCATENATE(A31,D31,B31) -> 1789252 | I31: =IF(A31=A30,CONCATENATE(I30," ",H31),H31) -> Service cambio de aceite y filtros. | K31: Kit de filtros | P31: 1 | Q31: 39000 | R31: =Q31*P31 -> 39000 | S31: 1 | T31: 30000 | U31: =+T31*S31 -> 30000 | V31: =IF(A31=A30,V30+U31,U31) -> 30000
A32: 18 | B32: =IF(A32=A31,B31+1,1) -> 1 | C32: 45140 | D32: Martina Nilda | E32: =CONCATENATE(A32,D32,B32) -> 18Martina Nilda1 | I32: =IF(A32=A31,CONCATENATE(I31," ",H32),H32) -> 0 | K32: Radiador de agua | P32: 1 | Q32: 79800 | R32: =Q32*P32 -> 79800 | U32: =+T32*S32 -> 0 | V32: =IF(A32=A31,V31+U32,U32) -> 0
A33: 18 | B33: =IF(A33=A32,B32+1,1) -> 2 | C33: =IF(A33=A32,C32,"") -> 45140 | D33: =IF(A33=A32,D32,"") -> Martina Nilda | E33: =CONCATENATE(A33,D33,B33) -> 18Martina Nilda2 | I33: =IF(A33=A32,CONCATENATE(I32," ",H33),H33) -> 0 | K33: Radiador de aire acondicionado | P33: 1 | Q33: 85500 | R33: =Q33*P33 -> 85500 | U33: =+T33*S33 -> 0 | V33: =IF(A33=A32,V32+U33,U33) -> 0
A34: 18 | B34: =IF(A34=A33,B33+1,1) -> 3 | C34: =IF(A34=A33,C33,"") -> 45140 | D34: =IF(A34=A33,D33,"") -> Martina Nilda | E34: =CONCATENATE(A34,D34,B34) -> 18Martina Nilda3 | I34: =IF(A34=A33,CONCATENATE(I33," ",H34),H34) -> 0 | K34: Electro de aire acondicionado | P34: 1 | Q34: 39900 | R34: =Q34*P34 -> 39900 | U34: =+T34*S34 -> 0 | V34: =IF(A34=A33,V33+U34,U34) -> 0
A35: 18 | B35: =IF(A35=A34,B34+1,1) -> 4 | C35: =IF(A35=A34,C34,"") -> 45140 | D35: =IF(A35=A34,D34,"") -> Martina Nilda | E35: =CONCATENATE(A35,D35,B35) -> 18Martina Nilda4 | I35: =IF(A35=A34,CONCATENATE(I34," ",H35),H35) -> 0 | K35: Electro de radiador de agua | P35: 1 | Q35: 39900 | R35: =Q35*P35 -> 39900 | S35: 1 | T35: 57000 | U35: =+T35*S35 -> 57000 | V35: =IF(A35=A34,V34+U35,U35) -> 57000
A36: 18 | B36: =IF(A36=A35,B35+1,1) -> 5 | C36: =IF(A36=A35,C35,"") -> 45140 | D36: =IF(A36=A35,D35,"") -> Martina Nilda | E36: =CONCATENATE(A36,D36,B36) -> 18Martina Nilda5 | I36: =IF(A36=A35,CONCATENATE(I35," ",H36),H36) -> 0 | K36: refrigerante + agua destilada | P36: 1 | Q36: 7000 | R36: =Q36*P36 -> 7000 | U36: =+T36*S36 -> 0 | V36: =IF(A36=A35,V35+U36,U36) -> 57000
A37: 18 | B37: =IF(A37=A36,B36+1,1) -> 6 | C37: =IF(A37=A36,C36,"") -> 45140 | D37: =IF(A37=A36,D36,"") -> Martina Nilda | E37: =CONCATENATE(A37,D37,B37) -> 18Martina Nilda6 | I37: =IF(A37=A36,CONCATENATE(I36," ",H37),H37) -> 0 | K37: carga de aire acondicionado | P37: 1 | Q37: 39900 | R37: =Q37*P37 -> 39900 | U37: =+T37*S37 -> 0 | V37: =IF(A37=A36,V36+U37,U37) -> 57000
A38: 19 | B38: =IF(A38=A37,B37+1,1) -> 1 | C38: 45146 | D38: Calderon Daniel | E38: =CONCATENATE(A38,D38,B38) -> 19Calderon Daniel1 | H38: Cambiar ambos amortiguadores. | I38: =IF(A38=A37,CONCATENATE(I37," ",H38),H38) -> Cambiar ambos amortiguadores. | K38: Amortiguadores delanteros | P38: 2 | Q38: 32000 | R38: =Q38*P38 -> 64000 | S38: 1 | T38: 23000 | U38: =+T38*S38 -> 23000 | V38: =IF(A38=A37,V37+U38,U38) -> 23000
A39: 19 | B39: =IF(A39=A38,B38+1,1) -> 2 | C39: =IF(A39=A38,C38,"") -> 45146 | D39: =IF(A39=A38,D38,"") -> Calderon Daniel | E39: =CONCATENATE(A39,D39,B39) -> 19Calderon Daniel2 | H39: Cambiar caño de agua. | I39: =IF(A39=A38,CONCATENATE(I38," ",H39),H39) -> Cambiar ambos amortiguadores. Cambiar caño de agua. | K39: Casoletas suspensión completa | P39: 2 | Q39: 14500 | R39: =Q39*P39 -> 29000 | U39: =+T39*S39 -> 0 | V39: =IF(A39=A38,V38+U39,U39) -> 23000
A40: 19 | B40: =IF(A40=A39,B39+1,1) -> 3 | C40: =IF(A40=A39,C39,"") -> 45146 | D40: =IF(A40=A39,D39,"") -> Calderon Daniel | E40: =CONCATENATE(A40,D40,B40) -> 19Calderon Daniel3 | I40: =IF(A40=A39,CONCATENATE(I39," ",H40),H40) -> Cambiar ambos amortiguadores. Cambiar caño de agua. | K40: Caño de agua | P40: 1 | Q40: 8000 | R40: =Q40*P40 -> 8000 | U40: =+T40*S40 -> 0 | V40: =IF(A40=A39,V39+U40,U40) -> 23000
A41: 20 | B41: =IF(A41=A40,B40+1,1) -> 1 | C41: 45152 | D41: Creativity S.A.S | E41: =CONCATENATE(A41,D41,B41) -> 20Creativity S.A.S1 | G41: Fiorino | H41: Service cambio de aceite y filtros. | I41: =IF(A41=A40,CONCATENATE(I40," ",H41),H41) -> Service cambio de aceite y filtros. | K41: Aceite motor 10w40 | P41: 4 | Q41: 3575 | R41: =Q41*P41 -> 14300 | U41: =+T41*S41 -> 0 | V41: =IF(A41=A40,V40+U41,U41) -> 0
...

Sheet Presupuesto
A1: PRESUPUESTO
A3: De Cristian Bongiovanni | C3: Comprob: | D3: 224
A4: Domicilio: Gral. Deheza 191 (6120) Laboulaye | C4: Fecha: | D4: =VLOOKUP(D3,'Carga Presup.'!A5:U664,3,0) -> #N/A
A7: Razón social: | B7: =VLOOKUP(D3,'Carga Presup.'!A5:U7262,4,0) -> Luciano Napoli
A8: Vehiculo: | B8: =VLOOKUP(D3,'Carga Presup.'!A5:U7262,7,0) -> Peugeot 307 | C8: Dominio: | D8: =VLOOKUP(D3,'Carga Presup.'!A5:V7261,6,0) -> 0
A11: Diagnóstico: | B11: =VLOOKUP(CONCATENATE(D3,B7,COUNT(A18:A39)),'Carga Presup.'!E5:V69261,5,0) -> Desarmar suspension de ambos lados. Sacar ambos amortiguadores completos. Reparar con cazoletas nuevas. Armado total. Regulacion de convergencia.
A16: Producto/servicio | C16: Cant. | D16: Precio Unit. | E16: Importe
A17: 5 | B17: Mano de obra | C17: 1 | D17: =VLOOKUP(CONCATENATE(D3,B7,COUNT(A18:A39)),'Carga Presup.'!E5:V69261,18,0) -> 150000 | E17: =IFERROR(D17*C17,"") -> 150000
A18: =IFERROR(VLOOKUP(CONCATENATE(D3,B7,1),'Carga Presup.'!E5:V69261,6,0),"") -> 0 | B18: =IFERROR(VLOOKUP(CONCATENATE(D3,B7,1),'Carga Presup.'!E5:V69261,7,0),"") -> Cazoletas | C18: =IFERROR(VLOOKUP(CONCATENATE(D3,B7,1),'Carga Presup.'!E5:V69261,12,0),"") -> 2 | D18: =IFERROR(VLOOKUP(CONCATENATE(D3,B7,1),'Carga Presup.'!E5:V69261,13,0),"") -> 43000 | E18: =IFERROR(D18*C18,"") -> 86000
A19: =IFERROR(VLOOKUP(CONCATENATE(D3,B7,2),'Carga Presup.'!E5:V69261,6,0),"") -> 0 | B19: =IFERROR(VLOOKUP(CONCATENATE(D3,B7,2),'Carga Presup.'!E5:V69261,7,0),"") -> 0 | C19: =IFERROR(VLOOKUP(CONCATENATE(D3,B7,2),'Carga Presup.'!E5:V69261,12,0),"") -> 0 | D19: =IFERROR(VLOOKUP(CONCATENATE(D3,B7,2),'Carga Presup.'!E5:V69261,13,0),"") -> 0 | E19: =IFERROR(D19*C19,"") -> 0
A20: =IFERROR(VLOOKUP(CONCATENATE($D$3,$B$7,3),'Carga Presup.'!$E$5:$V$69261,6,0),"") | B20: =IFERROR(VLOOKUP(CONCATENATE(D3,B7,3),'Carga Presup.'!E6:V69262,7,0),"") | C20: =IFERROR(VLOOKUP(CONCATENATE(D3,B7,3),'Carga Presup.'!E5:V69261,12,0),"") | D20: =IFERROR(VLOOKUP(CONCATENATE($D$3,$B$7,3),'Carga Presup.'!$E$5:$V$69261,13,0),"") | E20: =IFERROR(D20*C20,"")
A21: =IFERROR(VLOOKUP(CONCATENATE($D$3,$B$7,4),'Carga Presup.'!$E$5:$V$69261,6,0),"") | B21: =IFERROR(VLOOKUP(CONCATENATE($D$3,$B$7,4),'Carga Presup.'!$E$5:$V$69261,7,0),"") | C21: =IFERROR(VLOOKUP(CONCATENATE($D$3,$B$7,4),'Carga Presup.'!$E$5:$V$69261,12,0),"") | D21: =IFERROR(VLOOKUP(CONCATENATE($D$3,$B$7,4),'Carga Presup.'!$E$5:$V$69261,13,0),"") | E21: =IFERROR(D21*C21,"")
A22: =IFERROR(VLOOKUP(CONCATENATE($D$3,$B$7,5),'Carga Presup.'!$E$5:$V$69261,6,0),"") | B22: =IFERROR(VLOOKUP(CONCATENATE($D$3,$B$7,5),'Carga Presup.'!$E$5:$V$69261,7,0),"") | C22: =IFERROR(VLOOKUP(CONCATENATE($D$3,$B$7,5),'Carga Presup.'!$E$5:$V$69261,12,0),"") | D22: =IFERROR(VLOOKUP(CONCATENATE($D$3,$B$7,5),'Carga Presup.'!$E$5:$V$69261,13,0),"") | E22: =IFERROR(D22*C22,"")
A23: =IFERROR(VLOOKUP(CONCATENATE($D$3,$B$7,6),'Carga Presup.'!$E$5:$V$69261,6,0),"") | B23: =IFERROR(VLOOKUP(CONCATENATE($D$3,$B$7,6),'Carga Presup.'!$E$5:$V$69261,7,0),"") | C23: =IFERROR(VLOOKUP(CONCATENATE($D$3,$B$7,6),'Carga Presup.'!$E$5:$V$69261,12,0),"") | D23: =IFERROR(VLOOKUP(CONCATENATE($D$3,$B$7,6),'Carga Presup.'!$E$5:$V$69261,13,0),"") | E23: =IFERROR(D23*C23,"")
A24: =IFERROR(VLOOKUP(CONCATENATE($D$3,$B$7,7),'Carga Presup.'!$E$5:$V$69261,6,0),"") | B24: =IFERROR(VLOOKUP(CONCATENATE($D$3,$B$7,7),'Carga Presup.'!$E$5:$V$69261,7,0),"") | C24: =IFERROR(VLOOKUP(CONCATENATE($D$3,$B$7,7),'Carga Presup.'!$E$5:$V$69261,12,0),"") | D24: =IFERROR(VLOOKUP(CONCATENATE($D$3,$B$7,7),'Carga Presup.'!$E$5:$V$69261,13,0),"") | E24: =IFERROR(D24*C24,"")
A25: =IFERROR(VLOOKUP(CONCATENATE($D$3,$B$7,8),'Carga Presup.'!$E$5:$V$69261,6,0),"") | B25: =IFERROR(VLOOKUP(CONCATENATE($D$3,$B$7,8),'Carga Presup.'!$E$5:$V$69261,7,0),"") | C25: =IFERROR(VLOOKUP(CONCATENATE($D$3,$B$7,8),'Carga Presup.'!$E$5:$V$69261,12,0),"") | D25: =IFERROR(VLOOKUP(CONCATENATE($D$3,$B$7,8),'Carga Presup.'!$E$5:$V$69261,13,0),"") | E25: =IFERROR(D25*C25,"")
A26: =IFERROR(VLOOKUP(CONCATENATE($D$3,$B$7,9),'Carga Presup.'!$E$5:$V$69261,6,0),"") | B26: =IFERROR(VLOOKUP(CONCATENATE($D$3,$B$7,9),'Carga Presup.'!$E$5:$V$69261,7,0),"") | C26: =IFERROR(VLOOKUP(CONCATENATE($D$3,$B$7,9),'Carga Presup.'!$E$5:$V$69261,12,0),"") | D26: =IFERROR(VLOOKUP(CONCATENATE($D$3,$B$7,9),'Carga Presup.'!$E$5:$V$69261,13,0),"") | E26: =IFERROR(D26*C26,"")
A27: =IFERROR(VLOOKUP(CONCATENATE($D$3,$B$7,10),'Carga Presup.'!$E$5:$V$69261,6,0),"") | C27: =IFERROR(VLOOKUP(CONCATENATE($D$3,$B$7,10),'Carga Presup.'!$E$5:$V$69261,12,0),"") | D27: =IFERROR(VLOOKUP(CONCATENATE($D$3,$B$7,10),'Carga Presup.'!$E$5:$V$69261,13,0),"") | E27: =IFERROR(D27*C27,"")
B28: =IFERROR(VLOOKUP(CONCATENATE($D$3,$B$7,11),'Carga Presup.'!$E$5:$V$69261,7,0),"") | C28: =IFERROR(VLOOKUP(CONCATENATE($D$3,$B$7,11),'Carga Presup.'!$E$5:$V$69261,12,0),"") | D28: =IFERROR(VLOOKUP(CONCATENATE($D$3,$B$7,11),'Carga Presup.'!$E$5:$V$69261,13,0),"") | E28: =IFERROR(D28*C28,"")
C29: =IFERROR(VLOOKUP(CONCATENATE($D$3,$B$7,12),'Carga Presup.'!$E$5:$V$69261,12,0),"") | D29: =IFERROR(VLOOKUP(CONCATENATE($D$3,$B$7,12),'Carga Presup.'!$E$5:$V$69261,13,0),"") | E29: =IFERROR(D29*C29,"")
A30: =IFERROR(VLOOKUP(CONCATENATE($D$3,$B$7,13),'Carga Presup.'!$E$5:$V$69261,6,0),"") | B30: =IFERROR(VLOOKUP(CONCATENATE($D$3,$B$7,13),'Carga Presup.'!$E$5:$V$69261,7,0),"") | C30: =IFERROR(VLOOKUP(CONCATENATE($D$3,$B$7,13),'Carga Presup.'!$E$5:$V$69261,12,0),"") | D30: =IFERROR(VLOOKUP(CONCATENATE($D$3,$B$7,13),'Carga Presup.'!$E$5:$V$69261,13,0),"") | E30: =IFERROR(D30*C30,"")
A31: =IFERROR(VLOOKUP(CONCATENATE($D$3,$B$7,14),'Carga Presup.'!$E$5:$V$69261,6,0),"") | B31: =IFERROR(VLOOKUP(CONCATENATE($D$3,$B$7,14),'Carga Presup.'!$E$5:$V$69261,7,0),"") | C31: =IFERROR(VLOOKUP(CONCATENATE($D$3,$B$7,14),'Carga Presup.'!$E$5:$V$69261,12,0),"") | D31: =IFERROR(VLOOKUP(CONCATENATE($D$3,$B$7,14),'Carga Presup.'!$E$5:$V$69261,13,0),"") | E31: =IFERROR(D31*C31,"")
A32: =IFERROR(VLOOKUP(CONCATENATE($D$3,$B$7,15),'Carga Presup.'!$E$5:$V$69261,6,0),"") | B32: =IFERROR(VLOOKUP(CONCATENATE($D$3,$B$7,15),'Carga Presup.'!$E$5:$V$69261,7,0),"") | C32: =IFERROR(VLOOKUP(CONCATENATE($D$3,$B$7,15),'Carga Presup.'!$E$5:$V$69261,12,0),"") | D32: =IFERROR(VLOOKUP(CONCATENATE($D$3,$B$7,15),'Carga Presup.'!$E$5:$V$69261,13,0),"") | E32: =IFERROR(D32*C32,"")
A33: =IFERROR(VLOOKUP(CONCATENATE($D$3,$B$7,16),'Carga Presup.'!$E$5:$V$69261,6,0),"") | B33: =IFERROR(VLOOKUP(CONCATENATE($D$3,$B$7,16),'Carga Presup.'!$E$5:$V$69261,7,0),"") | C33: =IFERROR(VLOOKUP(CONCATENATE($D$3,$B$7,16),'Carga Presup.'!$E$5:$V$69261,12,0),"") | D33: =IFERROR(VLOOKUP(CONCATENATE($D$3,$B$7,16),'Carga Presup.'!$E$5:$V$69261,13,0),"") | E33: =IFERROR(D33*C33,"")
A34: =IFERROR(VLOOKUP(CONCATENATE($D$3,$B$7,17),'Carga Presup.'!$E$5:$V$69261,6,0),"") | B34: =IFERROR(VLOOKUP(CONCATENATE($D$3,$B$7,17),'Carga Presup.'!$E$5:$V$69261,7,0),"") | C34: =IFERROR(VLOOKUP(CONCATENATE($D$3,$B$7,17),'Carga Presup.'!$E$5:$V$69261,12,0),"") | D34: =IFERROR(VLOOKUP(CONCATENATE($D$3,$B$7,17),'Carga Presup.'!$E$5:$V$69261,13,0),"") | E34: =IFERROR(D34*C34,"")
B35: =IFERROR(VLOOKUP(CONCATENATE($D$3,$B$7,18),'Carga Presup.'!$E$5:$V$69261,7,0),"") | C35: =IFERROR(VLOOKUP(CONCATENATE($D$3,$B$7,18),'Carga Presup.'!$E$5:$V$69261,12,0),"") | D35: =IFERROR(VLOOKUP(CONCATENATE($D$3,$B$7,18),'Carga Presup.'!$E$5:$V$69261,13,0),"") | E35: =IFERROR(D35*C35,"")
A36: =IFERROR(VLOOKUP(CONCATENATE($D$3,$B$7,19),'Carga Presup.'!$E$5:$V$69261,6,0),"") | B36: =IFERROR(VLOOKUP(CONCATENATE($D$3,$B$7,19),'Carga Presup.'!$E$5:$V$69261,7,0),"") | C36: =IFERROR(VLOOKUP(CONCATENATE($D$3,$B$7,19),'Carga Presup.'!$E$5:$V$69261,12,0),"") | D36: =IFERROR(VLOOKUP(CONCATENATE($D$3,$B$7,19),'Carga Presup.'!$E$5:$V$69261,13,0),"") | E36: =IFERROR(D36*C36,"")
A37: =IFERROR(VLOOKUP(CONCATENATE($D$3,$B$7,20),'Carga Presup.'!$E$5:$V$69261,6,0),"") | B37: =IFERROR(VLOOKUP(CONCATENATE($D$3,$B$7,20),'Carga Presup.'!$E$5:$V$69261,7,0),"") | C37: =IFERROR(VLOOKUP(CONCATENATE($D$3,$B$7,20),'Carga Presup.'!$E$5:$V$69261,12,0),"") | D37: =IFERROR(VLOOKUP(CONCATENATE($D$3,$B$7,20),'Carga Presup.'!$E$5:$V$69261,13,0),"") | E37: =IFERROR(D37*C37,"")
A38: =IFERROR(VLOOKUP(CONCATENATE($D$3,$B$7,21),'Carga Presup.'!$E$5:$V$69261,6,0),"") | B38: =IFERROR(VLOOKUP(CONCATENATE($D$3,$B$7,21),'Carga Presup.'!$E$5:$V$69261,7,0),"") | C38: =IFERROR(VLOOKUP(CONCATENATE($D$3,$B$7,21),'Carga Presup.'!$E$5:$V$69261,12,0),"") | D38: =IFERROR(VLOOKUP(CONCATENATE($D$3,$B$7,21),'Carga Presup.'!$E$5:$V$69261,13,0),"") | E38: =IFERROR(D38*C38,"")
A41: Este presupuesto tiene validez por 15 días. | E41: TOTAL
E42: =SUM(E17:E39) -> 236000
H209: Service completo del vehiculo. El valor del servicio abarca el control de mas de 50 puntos del automovil.
A215: 64 | C215: 45231 | D215: Boschiaso Antonella | F215: JWE950 | G215: VW Vento 2.5 | H215: Service completo del vehiculo. El valor del servicio abarca el control de mas de 50 puntos del automovil. | K215: Kit de filtros | P215: 1 | Q215: 59000 | S215: 1 | T215: 41400
A216: 64 | K216: Aceite motor 5w40 | P216: 6 | Q216: 6950
M1791: taller
AB3599: 200000

Sheet % recargo
A1: PORCENTAJES DE REFERENCIA | D1: REFERENCIA MO
A2: REPUESTO | B2: % | D2: TRABAJO | E2: COSTO
A3: TODOS LOS REPUESTOS | B3: 0.2 | D3: HORA | E3: 4500
D4: SERVICE AUTO | E4: 5600
D5: SERVICE CAMIONETA | E5: 6500
D6: DIAGNÓSTICO (conectar scaner) | E6: 0

Sheet Base rep.
A1: CÓDIGO | B1: DESCRIPCIÓN
A2: 1 | B2: ALINEACION Y BALANCEO
A3: 2 | B3: SERVICE
A4: 3 | B4: TREN DELANTERO
A5: 4 | B5: SERVICIO TERCERO
A6: 5 | B6: MANO DE OBRA
