Workbook

Sheet Pagos clientes
D2: PAGOS DE CLIENTES
G3: =MATCH(G4,'Carga Remito.'!A3:AQ3,0) -> 37
A4: Nro comp. | B4: Fecha | C4: Meses de deuda | D4: Cliente | E4: Dominio | F4: Vehículo | G4: Total trabajo | H4: Fecha final pago | I4: Método pago | J4: Deuda | K4: Entrega 1 | L4: Fecha 1 | M4: Nº recibo | N4: Entrega 2 | O4: Fecha 2 | P4: Nº recibo | Q4: Entrega 3 | R4: Fecha 3 | S4: Nº recibo | T4: Entrega 4 | U4: Fecha 4 | V4: Nº recibo | W4: Entrega 5 | X4: Fecha 5 | Y4: Nº recibo | Z4: Entrega 6 | AA4: Fecha 6 | AB4: Nº recibo | AC4: Comentraio
A5: 1111 | B5: =VLOOKUP(A5,'Carga Remito.'!A$4:AK$16957,3,0) -> 45111 | C5: =ROUNDUP(IF((TODAY()-B5)<30,0,(TODAY()-B5)/30),0) -> 18 | D5: =VLOOKUP(A5,'Carga Remito.'!A$4:AK$15957,4,0) -> Gonzalez Alberto | E5: =VLOOKUP(A5,'Carga Remito.'!A$4:AK$2258,6,0) -> 0 | F5: =VLOOKUP(A5,'Carga Remito.'!A$4:AK$1858,7,0) -> Cronos | G5: =VLOOKUP(A5,'Carga Remito.'!A$4:AK$20957,MATCH(G$4,'Carga Remito.'!A$3:AQ$3,0),0) -> 64450 | I5: Efectivo | J5: =+G5-K5-N5-Q5-T5-W5-Z5 -> 0 | K5: 64450 | L5: 45112
A6: 1114 | B6: =VLOOKUP(A6,'Carga Remito.'!A$4:AK$16957,3,0) -> 45112 | C6: =ROUNDUP(IF((TODAY()-B6)<30,0,(TODAY()-B6)/30),0) -> 18 | D6: =VLOOKUP(A6,'Carga Remito.'!A$4:AK$15957,4,0) -> Hoyos Pato | E6: =VLOOKUP(A6,'Carga Remito.'!A$4:AK$2258,6,0) -> 0 | F6: =VLOOKUP(A6,'Carga Remito.'!A$4:AK$1858,7,0) -> Partner | G6: =VLOOKUP(A6,'Carga Remito.'!A$4:AK$20957,MATCH(G$4,'Carga Remito.'!A$3:AQ$3,0),0) -> 28000 | I6: Efectivo | J6: =+G6-K6-N6-Q6-T6-W6-Z6 -> 0 | K6: 28000 | L6: 45141
A7: 1117 | B7: =VLOOKUP(A7,'Carga Remito.'!A$4:AK$16957,3,0) -> 45112 | C7: =ROUNDUP(IF((TODAY()-B7)<30,0,(TODAY()-B7)/30),0) -> 18 | D7: =VLOOKUP(A7,'Carga Remito.'!A$4:AK$15957,4,0) -> Pisani Nicolas | E7: =VLOOKUP(A7,'Carga Remito.'!A$4:AK$2258,6,0) -> 0 | F7: =VLOOKUP(A7,'Carga Remito.'!A$4:AK$1858,7,0) -> Megane | G7: =VLOOKUP(A7,'Carga Remito.'!A$4:AK$20957,MATCH(G$4,'Carga Remito.'!A$3:AQ$3,0),0) -> 51260 | I7: Efectivo | J7: =+G7-K7-N7-Q7-T7-W7-Z7 -> 0 | K7: 51260 | L7: 45134
A8: 1118 | B8: =VLOOKUP(A8,'Carga Remito.'!A$4:AK$16957,3,0) -> 45112 | C8: =ROUNDUP(IF((TODAY()-B8)<30,0,(TODAY()-B8)/30),0) -> 18 | D8: =VLOOKUP(A8,'Carga Remito.'!A$4:AK$15957,4,0) -> Acotto Jorge | E8: =VLOOKUP(A8,'Carga Remito.'!A$4:AK$2258,6,0) -> 0 | F8: =VLOOKUP(A8,'Carga Remito.'!A$4:AK$1858,7,0) -> 147 | G8: =VLOOKUP(A8,'Carga Remito.'!A$4:AK$20957,MATCH(G$4,'Carga Remito.'!A$3:AQ$3,0),0) -> 32040 | I8: Efectivo | J8: =+G8-K8-N8-Q8-T8-W8-Z8 -> 0 | K8: 32040 | L8: 45118
A9: 1119 | B9: =VLOOKUP(A9,'Carga Remito.'!A$4:AK$16957,3,0) -> 45113 | C9: =ROUNDUP(IF((TODAY()-B9)<30,0,(TODAY()-B9)/30),0) -> 18 | D9: =VLOOKUP(A9,'Carga Remito.'!A$4:AK$15957,4,0) -> Crocinelli Carlos | E9: =VLOOKUP(A9,'Carga Remito.'!A$4:AK$2258,6,0) -> FXU688 | F9: =VLOOKUP(A9,'Carga Remito.'!A$4:AK$1858,7,0) -> GolTrend | G9: =VLOOKUP(A9,'Carga Remito.'!A$4:AK$20957,MATCH(G$4,'Carga Remito.'!A$3:AQ$3,0),0) -> 53695 | J9: =+G9-K9-N9-Q9-T9-W9-Z9 -> 0 | K9: 53695 | L9: 45129
A10: 1120 | B10: =VLOOKUP(A10,'Carga Remito.'!A$4:AK$16957,3,0) -> 45114 | C10: =ROUNDUP(IF((TODAY()-B10)<30,0,(TODAY()-B10)/30),0) -> 18 | D10: =VLOOKUP(A10,'Carga Remito.'!A$4:AK$15957,4,0) -> Martin Jose | E10: =VLOOKUP(A10,'Carga Remito.'!A$4:AK$2258,6,0) -> AC369PI | F10: =VLOOKUP(A10,'Carga Remito.'!A$4:AK$1858,7,0) -> 0 | G10: =VLOOKUP(A10,'Carga Remito.'!A$4:AK$20957,MATCH(G$4,'Carga Remito.'!A$3:AQ$3,0),0) -> 102000 | I10: Efectivo | J10: =+G10-K10-N10-Q10-T10-W10-Z10 -> 0 | K10: 102000 | L10: 45114
A11: 1121 | B11: =VLOOKUP(A11,'Carga Remito.'!A$4:AK$16957,3,0) -> 45114 | C11: =ROUNDUP(IF((TODAY()-B11)<30,0,(TODAY()-B11)/30),0) -> 18 | D11: =VLOOKUP(A11,'Carga Remito.'!A$4:AK$15957,4,0) -> Formini Victor | E11: =VLOOKUP(A11,'Carga Remito.'!A$4:AK$2258,6,0) -> 0 | F11: =VLOOKUP(A11,'Carga Remito.'!A$4:AK$1858,7,0) -> 0 | G11: =VLOOKUP(A11,'Carga Remito.'!A$4:AK$20957,MATCH(G$4,'Carga Remito.'!A$3:AQ$3,0),0) -> 10900 | I11: Efectivo | J11: =+G11-K11-N11-Q11-T11-W11-Z11 -> 0 | K11: 10900 | L11: 45114
A12: 1122 | B12: =VLOOKUP(A12,'Carga Remito.'!A$4:AK$16957,3,0) -> 45114 | C12: =ROUNDUP(IF((TODAY()-B12)<30,0,(TODAY()-B12)/30),0) -> 18 | D12: =VLOOKUP(A12,'Carga Remito.'!A$4:AK$15957,4,0) -> Carrara Luis (bocha) | E12: =VLOOKUP(A12,'Carga Remito.'!A$4:AK$2258,6,0) -> AD225VD | F12: =VLOOKUP(A12,'Carga Remito.'!A$4:AK$1858,7,0) -> Citroen C4 LOUNGE | G12: =VLOOKUP(A12,'Carga Remito.'!A$4:AK$20957,MATCH(G$4,'Carga Remito.'!A$3:AQ$3,0),0) -> 46000 | J12: =+G12-K12-N12-Q12-T12-W12-Z12 -> 0 | K12: 21800 | L12: 45148 | N12: 4200 | O12: 45131 | Q12: 20000 | R12: 45227
A13: 1123 | B13: =VLOOKUP(A13,'Carga Remito.'!A$4:AK$16957,3,0) -> 45114 | C13: =ROUNDUP(IF((TODAY()-B13)<30,0,(TODAY()-B13)/30),0) -> 18 | D13: =VLOOKUP(A13,'Carga Remito.'!A$4:AK$15957,4,0) -> Muñoz | E13: =VLOOKUP(A13,'Carga Remito.'!A$4:AK$2258,6,0) -> AO556QH | F13: =VLOOKUP(A13,'Carga Remito.'!A$4:AK$1858,7,0) -> Fiat Movie | G13: =VLOOKUP(A13,'Carga Remito.'!A$4:AK$20957,MATCH(G$4,'Carga Remito.'!A$3:AQ$3,0),0) -> 56700 | I13: Efectivo | J13: =+G13-K13-N13-Q13-T13-W13-Z13 -> 0 | K13: 56700 | L13: 45117
A14: 1124 | B14: =VLOOKUP(A14,'Carga Remito.'!A$4:AK$16957,3,0) -> 45114 | C14: =ROUNDUP(IF((TODAY()-B14)<30,0,(TODAY()-B14)/30),0) -> 18 | D14: =VLOOKUP(A14,'Carga Remito.'!A$4:AK$15957,4,0) -> Barroso Ruben | E14: =VLOOKUP(A14,'Carga Remito.'!A$4:AK$2258,6,0) -> 0 | F14: =VLOOKUP(A14,'Carga Remito.'!A$4:AK$1858,7,0) -> Ford Ranger | G14: =VLOOKUP(A14,'Carga Remito.'!A$4:AK$20957,MATCH(G$4,'Carga Remito.'!A$3:AQ$3,0),0) -> 153300 | I14: Efectivo | J14: =+G14-K14-N14-Q14-T14-W14-Z14 -> 0 | K14: 50000 | L14: 45146 | N14: 50000 | O14: 45182 | Q14: 50000 | R14: 45208 | T14: 3300 | U14: 45243
A15: 1125 | B15: =VLOOKUP(A15,'Carga Remito.'!A$4:AK$16957,3,0) -> 45114 | C15: =ROUNDUP(IF((TODAY()-B15)<30,0,(TODAY()-B15)/30),0) -> 18 | D15: =VLOOKUP(A15,'Carga Remito.'!A$4:AK$15957,4,0) -> Barroso Willy | E15: =VLOOKUP(A15,'Carga Remito.'!A$4:AK$2258,6,0) -> AE154FT | F15: =VLOOKUP(A15,'Carga Remito.'!A$4:AK$1858,7,0) -> Chevrolet Prisma | G15: =VLOOKUP(A15,'Carga Remito.'!A$4:AK$20957,MATCH(G$4,'Carga Remito.'!A$3:AQ$3,0),0) -> 98000 | J15: =+G15-K15-N15-Q15-T15-W15-Z15 -> 0 | K15: 98000 | L15: 45248
A16: 1126 | B16: =VLOOKUP(A16,'Carga Remito.'!A$4:AK$16957,3,0) -> 45117 | C16: =ROUNDUP(IF((TODAY()-B16)<30,0,(TODAY()-B16)/30),0) -> 18 | D16: =VLOOKUP(A16,'Carga Remito.'!A$4:AK$15957,4,0) -> Barroso Willy | E16: =VLOOKUP(A16,'Carga Remito.'!A$4:AK$2258,6,0) -> AE154FT | F16: =VLOOKUP(A16,'Carga Remito.'!A$4:AK$1858,7,0) -> Chevrolet Prisma | G16: =VLOOKUP(A16,'Carga Remito.'!A$4:AK$20957,MATCH(G$4,'Carga Remito.'!A$3:AQ$3,0),0) -> 220800 | J16: =+G16-K16-N16-Q16-T16-W16-Z16 -> 0 | K16: 100000 | L16: 45248 | N16: 100000 | O16: 45299 | Q16: 20800 | R16: 45310
A17: 1127 | B17: =VLOOKUP(A17,'Carga Remito.'!A$4:AK$16957,3,0) -> 45117 | C17: =ROUNDUP(IF((TODAY()-B17)<30,0,(TODAY()-B17)/30),0) -> 18 | D17: =VLOOKUP(A17,'Carga Remito.'!A$4:AK$15957,4,0) -> Lucero Adrian | E17: =VLOOKUP(A17,'Carga Remito.'!A$4:AK$2258,6,0) -> EFR454 | F17: =VLOOKUP(A17,'Carga Remito.'!A$4:AK$1858,7,0) -> Palio | G17: =VLOOKUP(A17,'Carga Remito.'!A$4:AK$20957,MATCH(G$4,'Carga Remito.'!A$3:AQ$3,0),0) -> 59250 | J17: =+G17-K17-N17-Q17-T17-W17-Z17 -> 0 | K17: 59250 | L17: 45120 | AC17: se le descontó un 10%
A18: 1128 | B18: =VLOOKUP(A18,'Carga Remito.'!A$4:AK$16957,3,0) -> 45117 | C18: =ROUNDUP(IF((TODAY()-B18)<30,0,(TODAY()-B18)/30),0) -> 18 | D18: =VLOOKUP(A18,'Carga Remito.'!A$4:AK$15957,4,0) -> Rodriguez Jorge | E18: =VLOOKUP(A18,'Carga Remito.'!A$4:AK$2258,6,0) -> AA255TK | F18: =VLOOKUP(A18,'Carga Remito.'!A$4:AK$1858,7,0) -> Siena | G18: =VLOOKUP(A18,'Carga Remito.'!A$4:AK$20957,MATCH(G$4,'Carga Remito.'!A$3:AQ$3,0),0) -> 103355 | I18: Transferencia | J18: =+G18-K18-N18-Q18-T18-W18-Z18 -> 0 | K18: 103355 | L18: 45119
A19: 1130 | B19: =VLOOKUP(A19,'Carga Remito.'!A$4:AK$16957,3,0) -> 45118 | C19: =ROUNDUP(IF((TODAY()-B19)<30,0,(TODAY()-B19)/30),0) -> 18 | D19: =VLOOKUP(A19,'Carga Remito.'!A$4:AK$15957,4,0) -> Lang Juan Pablo | E19: =VLOOKUP(A19,'Carga Remito.'!A$4:AK$2258,6,0) -> 0 | F19: =VLOOKUP(A19,'Carga Remito.'!A$4:AK$1858,7,0) -> Toro | G19: =VLOOKUP(A19,'Carga Remito.'!A$4:AK$20957,MATCH(G$4,'Carga Remito.'!A$3:AQ$3,0),0) -> 214300 | I19: transferencia | J19: =+G19-K19-N19-Q19-T19-W19-Z19 -> 0 | K19: 114300 | L19: 45138 | N19: 100000 | O19: 45181
A20: 1131 | B20: =VLOOKUP(A20,'Carga Remito.'!A$4:AK$16957,3,0) -> 45117 | C20: =ROUNDUP(IF((TODAY()-B20)<30,0,(TODAY()-B20)/30),0) -> 18 | D20: =VLOOKUP(A20,'Carga Remito.'!A$4:AK$15957,4,0) -> Orsa Antonio | E20: =VLOOKUP(A20,'Carga Remito.'!A$4:AK$2258,6,0) -> 0 | F20: =VLOOKUP(A20,'Carga Remito.'!A$4:AK$1858,7,0) -> Palio Wekend | G20: =VLOOKUP(A20,'Carga Remito.'!A$4:AK$20957,MATCH(G$4,'Carga Remito.'!A$3:AQ$3,0),0) -> 0 | I20: Efectivo | J20: =+G20-K20-N20-Q20-T20-W20-Z20 -> 0 | L20: 45117
A21: 1132 | B21: =VLOOKUP(A21,'Carga Remito.'!A$4:AK$16957,3,0) -> 45119 | C21: =ROUNDUP(IF((TODAY()-B21)<30,0,(TODAY()-B21)/30),0) -> 18 | D21: =VLOOKUP(A21,'Carga Remito.'!A$4:AK$15957,4,0) -> Martinich Nahuel | E21: =VLOOKUP(A21,'Carga Remito.'!A$4:AK$2258,6,0) -> AB767DV | F21: =VLOOKUP(A21,'Carga Remito.'!A$4:AK$1858,7,0) -> Palio | G21: =VLOOKUP(A21,'Carga Remito.'!A$4:AK$20957,MATCH(G$4,'Carga Remito.'!A$3:AQ$3,0),0) -> 73155 | I21: Efectivo | J21: =+G21-K21-N21-Q21-T21-W21-Z21 -> 0 | K21: 73155 | L21: 45119
A22: 1133 | B22: =VLOOKUP(A22,'Carga Remito.'!A$4:AK$16957,3,0) -> 45119 | C22: =ROUNDUP(IF((TODAY()-B22)<30,0,(TODAY()-B22)/30),0) -> 18 | D22: =VLOOKUP(A22,'Carga Remito.'!A$4:AK$15957,4,0) -> Bertaina Damian | E22: =VLOOKUP(A22,'Carga Remito.'!A$4:AK$2258,6,0) -> 0 | F22: =VLOOKUP(A22,'Carga Remito.'!A$4:AK$1858,7,0) -> Fiat Strada | G22: =VLOOKUP(A22,'Carga Remito.'!A$4:AK$20957,MATCH(G$4,'Carga Remito.'!A$3:AQ$3,0),0) -> 6500 | J22: =+G22-K22-N22-Q22-T22-W22-Z22 -> 0 | K22: 6500 | L22: 45125
A23: 1134 | B23: =VLOOKUP(A23,'Carga Remito.'!A$4:AK$16957,3,0) -> 45119 | C23: =ROUNDUP(IF((TODAY()-B23)<30,0,(TODAY()-B23)/30),0) -> 18 | D23: =VLOOKUP(A23,'Carga Remito.'!A$4:AK$15957,4,0) -> Isasis Luciana | E23: =VLOOKUP(A23,'Carga Remito.'!A$4:AK$2258,6,0) -> 0 | F23: =VLOOKUP(A23,'Carga Remito.'!A$4:AK$1858,7,0) -> Clio | G23: =VLOOKUP(A23,'Carga Remito.'!A$4:AK$20957,MATCH(G$4,'Carga Remito.'!A$3:AQ$3,0),0) -> 22000 | I23: transferencia | J23: =+G23-K23-N23-Q23-T23-W23-Z23 -> 0 | K23: 22000 | L23: 45142
A24: 1135 | B24: =VLOOKUP(A24,'Carga Remito.'!A$4:AK$16957,3,0) -> 45119 | C24: =ROUNDUP(IF((TODAY()-B24)<30,0,(TODAY()-B24)/30),0) -> 18 | D24: =VLOOKUP(A24,'Carga Remito.'!A$4:AK$15957,4,0) -> Oviedo Jose Luis | E24: =VLOOKUP(A24,'Carga Remito.'!A$4:AK$2258,6,0) -> 0 | F24: =VLOOKUP(A24,'Carga Remito.'!A$4:AK$1858,7,0) -> Daster F4R 4X4 | G24: =VLOOKUP(A24,'Carga Remito.'!A$4:AK$20957,MATCH(G$4,'Carga Remito.'!A$3:AQ$3,0),0) -> 81800 | I24: Efectivo | J24: =+G24-K24-N24-Q24-T24-W24-Z24 -> 0 | K24: 55000 | L24: 45119 | N24: 26800 | O24: 45174
A25: 1136 | B25: =VLOOKUP(A25,'Carga Remito.'!A$4:AK$16957,3,0) -> 45119 | C25: =ROUNDUP(IF((TODAY()-B25)<30,0,(TODAY()-B25)/30),0) -> 18 | D25: =VLOOKUP(A25,'Carga Remito.'!A$4:AK$15957,4,0) -> Guerrieri Gladys | E25: =VLOOKUP(A25,'Carga Remito.'!A$4:AK$2258,6,0) -> AB744KG | F25: =VLOOKUP(A25,'Carga Remito.'!A$4:AK$1858,7,0) -> Traker | G25: =VLOOKUP(A25,'Carga Remito.'!A$4:AK$20957,MATCH(G$4,'Carga Remito.'!A$3:AQ$3,0),0) -> 51620 | I25: Transferencia | J25: =+G25-K25-N25-Q25-T25-W25-Z25 -> 0 | K25: 51620 | L25: 45120
A26: 1137 | B26: =VLOOKUP(A26,'Carga Remito.'!A$4:AK$16957,3,0) -> 45119 | C26: =ROUNDUP(IF((TODAY()-B26)<30,0,(TODAY()-B26)/30),0) -> 18 | D26: =VLOOKUP(A26,'Carga Remito.'!A$4:AK$15957,4,0) -> Verdus Silvio | E26: =VLOOKUP(A26,'Carga Remito.'!A$4:AK$2258,6,0) -> LRY221 | F26: =VLOOKUP(A26,'Carga Remito.'!A$4:AK$1858,7,0) -> Aveo | G26: =VLOOKUP(A26,'Carga Remito.'!A$4:AK$20957,MATCH(G$4,'Carga Remito.'!A$3:AQ$3,0),0) -> 313300 | I26: Efectivo | J26: =+G26-K26-N26-Q26-T26-W26-Z26 -> 0 | K26: 160000 | L26: 45121 | N26: 60000 | O26: 45131 | Q26: 80000 | R26: 45152 | T26: 13300 | U26: 45160
A27: 1138 | B27: =VLOOKUP(A27,'Carga Remito.'!A$4:AK$16957,3,0) -> 45119 | C27: =ROUNDUP(IF((TODAY()-B27)<30,0,(TODAY()-B27)/30),0) -> 18 | D27: =VLOOKUP(A27,'Carga Remito.'!A$4:AK$15957,4,0) -> Gigante Joni | E27: =VLOOKUP(A27,'Carga Remito.'!A$4:AK$2258,6,0) -> 0 | F27: =VLOOKUP(A27,'Carga Remito.'!A$4:AK$1858,7,0) -> Saveiro 1,9 Diesel | G27: =VLOOKUP(A27,'Carga Remito.'!A$4:AK$20957,MATCH(G$4,'Carga Remito.'!A$3:AQ$3,0),0) -> 45600 | J27: =+G27-K27-N27-Q27-T27-W27-Z27 -> 0 | K27: 45600 | L27: 45155
A28: 1139 | B28: =VLOOKUP(A28,'Carga Remito.'!A$4:AK$16957,3,0) -> 45119 | C28: =ROUNDUP(IF((TODAY()-B28)<30,0,(TODAY()-B28)/30),0) -> 18 | D28: =VLOOKUP(A28,'Carga Remito.'!A$4:AK$15957,4,0) -> Fernandez Gerardo | E28: =VLOOKUP(A28,'Carga Remito.'!A$4:AK$2258,6,0) -> 0 | F28: =VLOOKUP(A28,'Carga Remito.'!A$4:AK$1858,7,0) -> Voyage | G28: =VLOOKUP(A28,'Carga Remito.'!A$4:AK$20957,MATCH(G$4,'Carga Remito.'!A$3:AQ$3,0),0) -> 42187.5 | J28: =+G28-K28-N28-Q28-T28-W28-Z28 -> 0 | K28: 30000 | L28: 45131 | N28: 12187.5 | O28: 45160
A29: 1140 | B29: =VLOOKUP(A29,'Carga Remito.'!A$4:AK$16957,3,0) -> 45120 | C29: =ROUNDUP(IF((TODAY()-B29)<30,0,(TODAY()-B29)/30),0) -> 17 | D29: =VLOOKUP(A29,'Carga Remito.'!A$4:AK$15957,4,0) -> Baner Abu Grillo | E29: =VLOOKUP(A29,'Carga Remito.'!A$4:AK$2258,6,0) -> 0 | F29: =VLOOKUP(A29,'Carga Remito.'!A$4:AK$1858,7,0) -> Gol Trend | G29: =VLOOKUP(A29,'Carga Remito.'!A$4:AK$20957,MATCH(G$4,'Carga Remito.'!A$3:AQ$3,0),0) -> 80700 | I29: transferencia | J29: =+G29-K29-N29-Q29-T29-W29-Z29 -> 0 | K29: 80700 | L29: 45134
A30: 1141 | B30: =VLOOKUP(A30,'Carga Remito.'!A$4:AK$16957,3,0) -> 45120 | C30: =ROUNDUP(IF((TODAY()-B30)<30,0,(TODAY()-B30)/30),0) -> 17 | D30: =VLOOKUP(A30,'Carga Remito.'!A$4:AK$15957,4,0) -> Ocampo Manolo | E30: =VLOOKUP(A30,'Carga Remito.'!A$4:AK$2258,6,0) -> 0 | F30: =VLOOKUP(A30,'Carga Remito.'!A$4:AK$1858,7,0) -> 0 | G30: =VLOOKUP(A30,'Carga Remito.'!A$4:AK$20957,MATCH(G$4,'Carga Remito.'!A$3:AQ$3,0),0) -> 0 | J30: =+G30-K30-N30-Q30-T30-W30-Z30 -> 0
A31: 1142 | B31: =VLOOKUP(A31,'Carga Remito.'!A$4:AK$16957,3,0) -> 45120 | C31: =ROUNDUP(IF((TODAY()-B31)<30,0,(TODAY()-B31)/30),0) -> 17 | D31: =VLOOKUP(A31,'Carga Remito.'!A$4:AK$15957,4,0) -> Wesek Pini | E31: =VLOOKUP(A31,'Carga Remito.'!A$4:AK$2258,6,0) -> 0 | F31: =VLOOKUP(A31,'Carga Remito.'!A$4:AK$1858,7,0) -> Agile | G31: =VLOOKUP(A31,'Carga Remito.'!A$4:AK$20957,MATCH(G$4,'Carga Remito.'!A$3:AQ$3,0),0) -> 39100 | J31: =+G31-K31-N31-Q31-T31-W31-Z31 -> 0 | K31: 39100 | L31: 45114
A32: 1143 | B32: =VLOOKUP(A32,'Carga Remito.'!A$4:AK$16957,3,0) -> 45120 | C32: =ROUNDUP(IF((TODAY()-B32)<30,0,(TODAY()-B32)/30),0) -> 17 | D32: =VLOOKUP(A32,'Carga Remito.'!A$4:AK$15957,4,0) -> Beriani Nazarena | E32: =VLOOKUP(A32,'Carga Remito.'!A$4:AK$2258,6,0) -> NEN775 | F32: =VLOOKUP(A32,'Carga Remito.'!A$4:AK$1858,7,0) -> Kangoo | G32: =VLOOKUP(A32,'Carga Remito.'!A$4:AK$20957,MATCH(G$4,'Carga Remito.'!A$3:AQ$3,0),0) -> 11300 | J32: =+G32-K32-N32-Q32-T32-W32-Z32 -> 0 | K32: 11300 | L32: 45120
A33: 1145 | B33: =VLOOKUP(A33,'Carga Remito.'!A$4:AK$16957,3,0) -> 45120 | C33: =ROUNDUP(IF((TODAY()-B33)<30,0,(TODAY()-B33)/30),0) -> 17 | D33: =VLOOKUP(A33,'Carga Remito.'!A$4:AK$15957,4,0) -> Macagno Dante | E33: =VLOOKUP(A33,'Carga Remito.'!A$4:AK$2258,6,0) -> LUX908 | F33: =VLOOKUP(A33,'Carga Remito.'!A$4:AK$1858,7,0) -> SIMBOL | G33: =VLOOKUP(A33,'Carga Remito.'!A$4:AK$20957,MATCH(G$4,'Carga Remito.'!A$3:AQ$3,0),0) -> 12000 | J33: =+G33-K33-N33-Q33-T33-W33-Z33 -> 0 | K33: 12000 | L33: 45132
A34: 1146 | B34: =VLOOKUP(A34,'Carga Remito.'!A$4:AK$16957,3,0) -> 45120 | C34: =ROUNDUP(IF((TODAY()-B34)<30,0,(TODAY()-B34)/30),0) -> 17 | D34: =VLOOKUP(A34,'Carga Remito.'!A$4:AK$15957,4,0) -> Macagno Omar | E34: =VLOOKUP(A34,'Carga Remito.'!A$4:AK$2258,6,0) -> OHT863 | F34: =VLOOKUP(A34,'Carga Remito.'!A$4:AK$1858,7,0) -> PALIO | G34: =VLOOKUP(A34,'Carga Remito.'!A$4:AK$20957,MATCH(G$4,'Carga Remito.'!A$3:AQ$3,0),0) -> 10200 | J34: =+G34-K34-N34-Q34-T34-W34-Z34 -> 0 | K34: 10200 | L34: 45132
A35: 1147 | B35: =VLOOKUP(A35,'Carga Remito.'!A$4:AK$16957,3,0) -> 45120 | C35: =ROUNDUP(IF((TODAY()-B35)<30,0,(TODAY()-B35)/30),0) -> 17 | D35: =VLOOKUP(A35,'Carga Remito.'!A$4:AK$15957,4,0) -> Weizek Susana | E35: =VLOOKUP(A35,'Carga Remito.'!A$4:AK$2258,6,0) -> JNW454 | F35: =VLOOKUP(A35,'Carga Remito.'!A$4:AK$1858,7,0) -> FOX | G35: =VLOOKUP(A35,'Carga Remito.'!A$4:AK$20957,MATCH(G$4,'Carga Remito.'!A$3:AQ$3,0),0) -> 49500 | I35: transferencia | J35: =+G35-K35-N35-Q35-T35-W35-Z35 -> 0 | K35: 49500 | L35: 45120
A36: 1148 | B36: =VLOOKUP(A36,'Carga Remito.'!A$4:AK$16957,3,0) -> 45121 | C36: =ROUNDUP(IF((TODAY()-B36)<30,0,(TODAY()-B36)/30),0) -> 17 | D36: =VLOOKUP(A36,'Carga Remito.'!A$4:AK$15957,4,0) -> Pujol Jorge | E36: =VLOOKUP(A36,'Carga Remito.'!A$4:AK$2258,6,0) -> 0 | F36: =VLOOKUP(A36,'Carga Remito.'!A$4:AK$1858,7,0) -> 0 | G36: =VLOOKUP(A36,'Carga Remito.'!A$4:AK$20957,MATCH(G$4,'Carga Remito.'!A$3:AQ$3,0),0) -> 36400 | I36: Efectivo | J36: =+G36-K36-N36-Q36-T36-W36-Z36 -> 0 | K36: 36400 | L36: 45121
A37: 1149 | B37: =VLOOKUP(A37,'Carga Remito.'!A$4:AK$16957,3,0) -> 45121 | C37: =ROUNDUP(IF((TODAY()-B37)<30,0,(TODAY()-B37)/30),0) -> 17 | D37: =VLOOKUP(A37,'Carga Remito.'!A$4:AK$15957,4,0) -> Pasini Carolina | E37: =VLOOKUP(A37,'Carga Remito.'!A$4:AK$2258,6,0) -> 0 | F37: =VLOOKUP(A37,'Carga Remito.'!A$4:AK$1858,7,0) -> C3 croos 16v | G37: =VLOOKUP(A37,'Carga Remito.'!A$4:AK$20957,MATCH(G$4,'Carga Remito.'!A$3:AQ$3,0),0) -> 17000 | I37: Efectivo | J37: =+G37-K37-N37-Q37-T37-W37-Z37 -> 0 | K37: 17000 | L37: 45121
A38: 1150 | B38: =VLOOKUP(A38,'Carga Remito.'!A$4:AK$16957,3,0) -> 45121 | C38: =ROUNDUP(IF((TODAY()-B38)<30,0,(TODAY()-B38)/30),0) -> 17 | D38: =VLOOKUP(A38,'Carga Remito.'!A$4:AK$15957,4,0) -> Carrara Sandra | E38: =VLOOKUP(A38,'Carga Remito.'!A$4:AK$2258,6,0) -> 0 | F38: =VLOOKUP(A38,'Carga Remito.'!A$4:AK$1858,7,0) -> Saveiro | G38: =VLOOKUP(A38,'Carga Remito.'!A$4:AK$20957,MATCH(G$4,'Carga Remito.'!A$3:AQ$3,0),0) -> 69961 | I38: cheque | J38: =+G38-K38-N38-Q38-T38-W38-Z38 -> 0 | K38: 69961 | L38: 45134
A39: 1151 | B39: =VLOOKUP(A39,'Carga Remito.'!A$4:AK$16957,3,0) -> 45131 | C39: =ROUNDUP(IF((TODAY()-B39)<30,0,(TODAY()-B39)/30),0) -> 17 | D39: =VLOOKUP(A39,'Carga Remito.'!A$4:AK$15957,4,0) -> Cuevas Jorge | E39: =VLOOKUP(A39,'Carga Remito.'!A$4:AK$2258,6,0) -> 0 | F39: =VLOOKUP(A39,'Carga Remito.'!A$4:AK$1858,7,0) -> Prisma | G39: =VLOOKUP(A39,'Carga Remito.'!A$4:AK$20957,MATCH(G$4,'Carga Remito.'!A$3:AQ$3,0),0) -> 16500 | I39: Transferencia | J39: =+G39-K39-N39-Q39-T39-W39-Z39 -> 0 | K39: 16500 | L39: 45133
A40: 1152 | B40: =VLOOKUP(A40,'Carga Remito.'!A$4:AK$16957,3,0) -> 45131 | C40: =ROUNDUP(IF((TODAY()-B40)<30,0,(TODAY()-B40)/30),0) -> 17 | D40: =VLOOKUP(A40,'Carga Remito.'!A$4:AK$15957,4,0) -> Weizur | E40: =VLOOKUP(A40,'Carga Remito.'!A$4:AK$2258,6,0) -> 0 | F40: =VLOOKUP(A40,'Carga Remito.'!A$4:AK$1858,7,0) -> Oroch | G40: =VLOOKUP(A40,'Carga Remito.'!A$4:AK$20957,MATCH(G$4,'Carga Remito.'!A$3:AQ$3,0),0) -> 76800 | I40: transferencia | J40: =+G40-K40-N40-Q40-T40-W40-Z40 -> 0 | K40: 76800 | L40: 45180
A41: 1153 | B41: =VLOOKUP(A41,'Carga Remito.'!A$4:AK$16957,3,0) -> 45131 | C41: =ROUNDUP(IF((TODAY()-B41)<30,0,(TODAY()-B41)/30),0) -> 17 | D41: =VLOOKUP(A41,'Carga Remito.'!A$4:AK$15957,4,0) -> Alvarez Guillermo | E41: =VLOOKUP(A41,'Carga Remito.'!A$4:AK$2258,6,0) -> 0 | F41: =VLOOKUP(A41,'Carga Remito.'!A$4:AK$1858,7,0) -> Sandero stepway MK4M | G41: =VLOOKUP(A41,'Carga Remito.'!A$4:AK$20957,MATCH(G$4,'Carga Remito.'!A$3:AQ$3,0),0) -> 13800 | I41: Efectivo | J41: =+G41-K41-N41-Q41-T41-W41-Z41 -> 0 | K41: 13800
...

Sheet Carga Remito.
A1: 1 | B1: 2 | C1: 3 | D1: 4 | E1: 5 | F1: 6 | G1: 7 | I1: 8 | J1: 9 | K1: 10 | M1: 11 | N1: 12 | Q1: 13 | R1: 14 | S1: 15 | T1: 16 | W1: 17 | X1: 18 | Y1: 19 | AB1: 20 | AC1: 21 | AD1: 22 | AE1: 23 | AF1: 24 | AG1: 25 | AH1: 26 | AK1: 27
G2: TRABAJOS REALIZADOS | S2: =(W2-Q2)/Q2 -> #DIV/0!
A3: Nro comp. | B3: contador | C3: Fecha | D3: Cliente | E3: Remito y cliente | F3: Dominio | G3: Vehículo | H3: Kilómetros | I3: Trabajo realizado | J3: CONCATENADO | K3: Responsable | L3: Codigo Repuesto | M3: Repuesto | N3: Proveedores | O3: Costo sin IVA | P3: IVA | Q3: Costo | R3: Tipo de trabajo | S3: % ganancia | T3: Cantidad | U3: Precio sin IVA | V3: IVA | W3: Precio final unitario repuesto | X3: Total | Y3: MO tiempo | Z3: Precio sin IVA | AA3: IVA | AB3: MO precio | AC3: MO | AD3: MO Acumulado | AE3: Costo repuestos | AF3: Total costo repuesto | AG3: Total precio repuesto | AH3: Total MO | AI3: Total trabajo sin IVA | AJ3: IVA | AK3: Total trabajo | AL3: NUMERO DE FACTURA | AN3: Responsable | AO3: Tipo de trabajo
A4: 1111 | B4: =IF(A4=A3,B3+1,1) -> 1 | C4: 45111 | D4: Gonzalez Alberto | E4: =CONCATENATE(A4,D4,B4) -> 1111Gonzalez Alberto1 | G4: Cronos | I4: Service cambio de aceite y filtro. | J4: =IF(A4=A3,CONCATENATE(J3," ",I4),I4) -> Service cambio de aceite y filtro. | L4: 1 | M4: Filtro aceite | N4: Taller | Q4: 1500 | R4: Service | S4: =+(W4-Q4)/Q4 -> 1.4 | T4: 1 | W4: 3600 | X4: =W4*T4 -> 3600 | AC4: =+AB4*Y4 -> 0 | AD4: =AC4 -> 0 | AE4: =+(Q4)*T4 -> 1500 | AF4: =SUM(AE4:AE8) -> 16672.411 | AG4: =SUM(X4:X8) -> 39450 | AH4: =AD8 -> 25000 | AK4: =AH4+AG4 -> 64450 | AN4: Emanuel | AO4: Service
A5: 1111 | B5: =IF(A5=A4,B4+1,1) -> 2 | C5: =IF(A5=A4,C4,"") -> 45111 | D5: =IF(A5=A4,D4,"") -> Gonzalez Alberto | E5: =CONCATENATE(A5,D5,B5) -> 1111Gonzalez Alberto2 | I5: Control general del vehículo. | J5: =IF(A5=A4,CONCATENATE(J4," ",I5),I5) -> Service cambio de aceite y filtro. Control general del vehículo. | L5: 1 | M5: Filtro aire | N5: Taller | Q5: 2000 | S5: =+(W5-Q5)/Q5 -> 1.4 | T5: 1 | W5: 4800 | X5: =W5*T5 -> 4800 | AC5: =+AB5*Y5 -> 0 | AD5: =IF(A5=A4,AD4+AC5,AC5) -> 0 | AE5: =+(Q5)*T5 -> 2000 | AF5: =IF(A5=A4,0,(SUMIF($A$3:$A$999956,A5,$Q$3:$Q$999956)))+IF(A5=A4,0,(SUMIF($A$3:$A$999956,A5,$R$3:$R$999956))) -> 0 | AG5: =IF(A5=A4,0,(SUMIF($A$3:$A$999956,A5,($X$3:$X$999956)))) -> 0 | AH5: =IF(A5=A4,0,(SUMIF($A$3:$A$999956,A5,($AC$3:$AC$999956)))) -> 0 | AK5: =AH5+AG5 -> 0 | AN5: Federico | AO5: Distribución
A6: 1111 | B6: =IF(A6=A5,B5+1,1) -> 3 | C6: =IF(A6=A5,C5,"") -> 45111 | D6: =IF(A6=A5,D5,"") -> Gonzalez Alberto | E6: =CONCATENATE(A6,D6,B6) -> 1111Gonzalez Alberto3 | I6: Lavado motor. | J6: =IF(A6=A5,CONCATENATE(J5," ",I6),I6) -> Service cambio de aceite y filtro. Control general del vehículo. Lavado motor. | L6: 1 | M6: Filtro nafta | N6: Taller | Q6: 2000 | S6: =+(W6-Q6)/Q6 -> 0.9 | T6: 1 | W6: 3800 | X6: =W6*T6 -> 3800 | AC6: =+AB6*Y6 -> 0 | AD6: =IF(A6=A5,AD5+AC6,AC6) -> 0 | AE6: =+(Q6)*T6 -> 2000 | AF6: =IF(A6=A5,0,(SUMIF($A$3:$A$999956,A6,$Q$3:$Q$999956)))+IF(A6=A5,0,(SUMIF($A$3:$A$999956,A6,$R$3:$R$999956))) -> 0 | AG6: =IF(A6=A5,0,(SUMIF($A$3:$A$999956,A6,($X$3:$X$999956)))) -> 0 | AH6: =IF(A6=A5,0,(SUMIF($A$3:$A$999956,A6,($AC$3:$AC$999956)))) -> 0 | AK6: =AH6+AG6 -> 0 | AN6: Cristian | AO6: Motor
A7: 1111 | B7: =IF(A7=A6,B6+1,1) -> 4 | C7: =IF(A7=A6,C6,"") -> 45111 | D7: =IF(A7=A6,D6,"") -> Gonzalez Alberto | E7: =CONCATENATE(A7,D7,B7) -> 1111Gonzalez Alberto4 | I7: Rotación de ruedas. | J7: =IF(A7=A6,CONCATENATE(J6," ",I7),I7) -> Service cambio de aceite y filtro. Control general del vehículo. Lavado motor. Rotación de ruedas. | L7: 1 | M7: Filtro pólen | N7: Taller | Q7: =+W7/(1+S7) -> 1666.6667 | S7: 0.5 | T7: 1 | W7: 2500 | X7: =W7*T7 -> 2500 | AC7: =+AB7*Y7 -> 0 | AD7: =IF(A7=A6,AD6+AC7,AC7) -> 0 | AE7: =+(Q7)*T7 -> 1666.6667 | AF7: =IF(A7=A6,0,(SUMIF($A$3:$A$999956,A7,$Q$3:$Q$999956)))+IF(A7=A6,0,(SUMIF($A$3:$A$999956,A7,$R$3:$R$999956))) -> 0 | AG7: =IF(A7=A6,0,(SUMIF($A$3:$A$999956,A7,($X$3:$X$999956)))) -> 0 | AH7: =IF(A7=A6,0,(SUMIF($A$3:$A$999956,A7,($AC$3:$AC$999956)))) -> 0 | AK7: =AH7+AG7 -> 0 | AN7: Juan Carlos | AO7: Otros
A8: 1111 | B8: =IF(A8=A7,B7+1,1) -> 5 | C8: =IF(A8=A7,C7,"") -> 45111 | D8: =IF(A8=A7,D7,"") -> Gonzalez Alberto | E8: =CONCATENATE(A8,D8,B8) -> 1111Gonzalez Alberto5 | J8: =IF(A8=A7,CONCATENATE(J7," ",I8),I8) -> Service cambio de aceite y filtro. Control general del vehículo. Lavado motor. Rotación de ruedas. | L8: 1 | M8: Aceite 5w30 | N8: Taller | Q8: =441489/209 -> 2112.3876 | S8: 1.6036889 | T8: 4.5 | W8: 5500 | X8: =W8*T8 -> 24750 | Y8: 1 | AB8: 25000 | AC8: =+AB8*Y8 -> 25000 | AD8: =IF(A8=A7,AD7+AC8,AC8) -> 25000 | AE8: =+(Q8)*T8 -> 9505.744 | AF8: =IF(A8=A7,0,(SUMIF($A$3:$A$999956,A8,$Q$3:$Q$999956)))+IF(A8=A7,0,(SUMIF($A$3:$A$999956,A8,$R$3:$R$999956))) -> 0 | AG8: =IF(A8=A7,0,(SUMIF($A$3:$A$999956,A8,($X$3:$X$999956)))) -> 0 | AH8: =IF(A8=A7,0,(SUMIF($A$3:$A$999956,A8,($AC$3:$AC$999956)))) -> 0 | AK8: =AH8+AG8 -> 0 | AN8: Emanuel/Cristian
A9: 1112 | B9: =IF(A9=A8,B8+1,1) -> 1 | C9: 45111 | D9: Transporte del Interior | E9: =CONCATENATE(A9,D9,B9) -> 1112Transporte del Interior1 | F9: 993CE | G9: Fiorino | I9: Cambiar cables de bujias y bujias. | J9: =IF(A9=A8,CONCATENATE(J8," ",I9),I9) -> Cambiar cables de bujias y bujias. | L9: 1 | R9: Otros | W9: 0 | X9: =W9*T9 -> 0 | Y9: 1 | AB9: 7000 | AC9: =+AB9*Y9 -> 7000 | AD9: =IF(A9=A8,AD8+AC9,AC9) -> 7000 | AE9: =+(Q9)*T9 -> 0 | AF9: =IF(A9=A8,0,(SUMIF($A$3:$A$999956,A9,$AE$3:$AE$999956))) -> 0 | AG9: =IF(A9=A8,0,(SUMIF($A$3:$A$999956,A9,($X$3:$X$999956)))) -> 0 | AH9: =IF(A9=A8,0,(SUMIF($A$3:$A$999956,A9,($AC$3:$AC$999956)))) -> 7000 | AK9: =AH9+AG9 -> 7000 | AN9: Federico/Cristian
A10: 1113 | B10: =IF(A10=A9,B9+1,1) -> 1 | C10: 45111 | D10: Transporte del Interior | E10: =CONCATENATE(A10,D10,B10) -> 1113Transporte del Interior1 | G10: Peugeot 208 | I10: Service cambio de aceite y filtros. | J10: =IF(A10=A9,CONCATENATE(J9," ",I10),I10) -> Service cambio de aceite y filtros. | L10: 1 | M10: Aceite 10w40 | N10: Taller | Q10: 1214.8325 | R10: Service | S10: 1.572371 | T10: 4 | W10: 3125 | X10: =W10*T10 -> 12500 | AC10: =+AB10*Y10 -> 0 | AD10: =IF(A10=A9,AD9+AC10,AC10) -> 0 | AE10: =+(Q10)*T10 -> 4859.3301 | AF10: =IF(A10=A9,0,(SUMIF($A$3:$A$999956,A10,$AE$3:$AE$999956))) -> 12025.997 | AG10: =IF(A10=A9,0,(SUMIF($A$3:$A$999956,A10,($X$3:$X$999956)))) -> 26400 | AH10: =IF(A10=A9,0,(SUMIF($A$3:$A$999956,A10,($AC$3:$AC$999956)))) -> 18000 | AK10: =AH10+AG10 -> 44400 | AN10: Juan Carlos/Cristian
A11: 1113 | B11: =IF(A11=A10,B10+1,1) -> 2 | C11: =IF(A11=A10,C10,"") -> 45111 | D11: Transporte del Interior | E11: =CONCATENATE(A11,D11,B11) -> 1113Transporte del Interior2 | I11: Control del vehículo. | J11: =IF(A11=A10,CONCATENATE(J10," ",I11),I11) -> Service cambio de aceite y filtros. Control del vehículo. | L11: 1 | M11: Filto aceite | N11: Taller | Q11: 1500 | S11: =+(W11-Q11)/Q11 -> 1.4 | T11: 1 | W11: 3600 | X11: =W11*T11 -> 3600 | AC11: =+AB11*Y11 -> 0 | AD11: =IF(A11=A10,AD10+AC11,AC11) -> 0 | AE11: =+(Q11)*T11 -> 1500 | AF11: =IF(A11=A10,0,(SUMIF($A$3:$A$999956,A11,$AE$3:$AE$999956))) -> 0 | AG11: =IF(A11=A10,0,(SUMIF($A$3:$A$999956,A11,($X$3:$X$999956)))) -> 0 | AH11: =IF(A11=A10,0,(SUMIF($A$3:$A$999956,A11,($AC$3:$AC$999956)))) -> 0 | AK11: =AH11+AG11 -> 0 | AN11: Emanuel/Federico
A12: 1113 | B12: =IF(A12=A11,B11+1,1) -> 3 | C12: =IF(A12=A11,C11,"") -> 45111 | D12: Transporte del Interior | E12: =CONCATENATE(A12,D12,B12) -> 1113Transporte del Interior3 | I12: Rotación de ruedas. | J12: =IF(A12=A11,CONCATENATE(J11," ",I12),I12) -> Service cambio de aceite y filtros. Control del vehículo. Rotación de ruedas. | L12: 1 | M12: Filtro aire | N12: Taller | Q12: 2000 | S12: =+(W12-Q12)/Q12 -> 1.4 | T12: 1 | W12: 4800 | X12: =W12*T12 -> 4800 | AC12: =+AB12*Y12 -> 0 | AD12: =IF(A12=A11,AD11+AC12,AC12) -> 0 | AE12: =+(Q12)*T12 -> 2000 | AF12: =IF(A12=A11,0,(SUMIF($A$3:$A$999956,A12,$AE$3:$AE$999956))) -> 0 | AG12: =IF(A12=A11,0,(SUMIF($A$3:$A$999956,A12,($X$3:$X$999956)))) -> 0 | AH12: =IF(A12=A11,0,(SUMIF($A$3:$A$999956,A12,($AC$3:$AC$999956)))) -> 0 | AK12: =AH12+AG12 -> 0
A13: 1113 | B13: =IF(A13=A12,B12+1,1) -> 4 | C13: =IF(A13=A12,C12,"") -> 45111 | D13: Transporte del Interior | E13: =CONCATENATE(A13,D13,B13) -> 1113Transporte del Interior4 | J13: =IF(A13=A12,CONCATENATE(J12," ",I13),I13) -> Service cambio de aceite y filtros. Control del vehículo. Rotación de ruedas. | L13: 1 | M13: Filtro nafta | N13: Taller | Q13: 2000 | S13: =+(W13-Q13)/Q13 -> 0.5 | T13: 1 | W13: 3000 | X13: =W13*T13 -> 3000 | AC13: =+AB13*Y13 -> 0 | AD13: =IF(A13=A12,AD12+AC13,AC13) -> 0 | AE13: =+(Q13)*T13 -> 2000 | AF13: =IF(A13=A12,0,(SUMIF($A$3:$A$999956,A13,$AE$3:$AE$999956))) -> 0 | AG13: =IF(A13=A12,0,(SUMIF($A$3:$A$999956,A13,($X$3:$X$999956)))) -> 0 | AH13: =IF(A13=A12,0,(SUMIF($A$3:$A$999956,A13,($AC$3:$AC$999956)))) -> 0 | AK13: =AH13+AG13 -> 0
A14: 1113 | B14: =IF(A14=A13,B13+1,1) -> 5 | C14: =IF(A14=A13,C13,"") -> 45111 | D14: Transporte del Interior | E14: =CONCATENATE(A14,D14,B14) -> 1113Transporte del Interior5 | J14: =IF(A14=A13,CONCATENATE(J13," ",I14),I14) -> Service cambio de aceite y filtros. Control del vehículo. Rotación de ruedas. | L14: 1 | M14: Filtro pólen | N14: Taller | Q14: =+W14/(1+S14) -> 1666.6667 | S14: 0.5 | T14: 1 | W14: 2500 | X14: =W14*T14 -> 2500 | Y14: 1 | AB14: 18000 | AC14: =+AB14*Y14 -> 18000 | AD14: =IF(A14=A13,AD13+AC14,AC14) -> 18000 | AE14: =+(Q14)*T14 -> 1666.6667 | AF14: =IF(A14=A13,0,(SUMIF($A$3:$A$999956,A14,$AE$3:$AE$999956))) -> 0 | AG14: =IF(A14=A13,0,(SUMIF($A$3:$A$999956,A14,($X$3:$X$999956)))) -> 0 | AH14: =IF(A14=A13,0,(SUMIF($A$3:$A$999956,A14,($AC$3:$AC$999956)))) -> 0 | AK14: =AH14+AG14 -> 0
A15: 1114 | B15: =IF(A15=A14,B14+1,1) -> 1 | C15: 45112 | D15: Hoyos Pato | E15: =CONCATENATE(A15,D15,B15) -> 1114Hoyos Pato1 | G15: Partner | I15: Scanear vehículo. | J15: =IF(A15=A14,CONCATENATE(J14," ",I15),I15) -> Scanear vehículo. | L15: 1 | M15: Bujia | N15: Taller | Q15: =+W15/(1+S15) -> 1666.6667 | R15: Otros | S15: 0.2 | T15: 4 | W15: 2000 | X15: =W15*T15 -> 8000 | Y15: 1 | AB15: 20000 | AC15: =+AB15*Y15 -> 20000 | AD15: =IF(A15=A14,AD14+AC15,AC15) -> 20000 | AE15: =+(Q15)*T15 -> 6666.6667 | AF15: =IF(A15=A14,0,(SUMIF($A$3:$A$999956,A15,$AE$3:$AE$999956))) -> 6666.6667 | AG15: =IF(A15=A14,0,(SUMIF($A$3:$A$999956,A15,($X$3:$X$999956)))) -> 8000 | AH15: =IF(A15=A14,0,(SUMIF($A$3:$A$999956,A15,($AC$3:$AC$999956)))) -> 20000 | AK15: =AH15+AG15 -> 28000
A16: 1114 | B16: =IF(A16=A15,B15+1,1) -> 2 | C16: =IF(A16=A15,C15,"") -> 45112 | D16: =IF(A16=A15,D15,"") -> Hoyos Pato | E16: =CONCATENATE(A16,D16,B16) -> 1114Hoyos Pato2 | I16: Limpieza del cuerpo mariposa. | J16: =IF(A16=A15,CONCATENATE(J15," ",I16),I16) -> Scanear vehículo. Limpieza del cuerpo mariposa. | L16: 1 | W16: 0 | X16: =W16*T16 -> 0 | AC16: =+AB16*Y16 -> 0 | AD16: =IF(A16=A15,AD15+AC16,AC16) -> 20000 | AE16: =+(Q16)*T16 -> 0 | AF16: =IF(A16=A15,0,(SUMIF($A$3:$A$999956,A16,$AE$3:$AE$999956))) -> 0 | AG16: =IF(A16=A15,0,(SUMIF($A$3:$A$999956,A16,($X$3:$X$999956)))) -> 0 | AH16: =IF(A16=A15,0,(SUMIF($A$3:$A$999956,A16,($AC$3:$AC$999956)))) -> 0 | AK16: =AH16+AG16 -> 0
A17: 1114 | B17: =IF(A17=A16,B16+1,1) -> 3 | C17: =IF(A17=A16,C16,"") -> 45112 | D17: =IF(A17=A16,D16,"") -> Hoyos Pato | E17: =CONCATENATE(A17,D17,B17) -> 1114Hoyos Pato3 | I17: Cambiar bujia de encendido. | J17: =IF(A17=A16,CONCATENATE(J16," ",I17),I17) -> Scanear vehículo. Limpieza del cuerpo mariposa. Cambiar bujia de encendido. | L17: 1 | W17: 0 | X17: =W17*T17 -> 0 | AC17: =+AB17*Y17 -> 0 | AD17: =IF(A17=A16,AD16+AC17,AC17) -> 20000 | AE17: =+(Q17)*T17 -> 0 | AF17: =IF(A17=A16,0,(SUMIF($A$3:$A$999956,A17,$AE$3:$AE$999956))) -> 0 | AG17: =IF(A17=A16,0,(SUMIF($A$3:$A$999956,A17,($X$3:$X$999956)))) -> 0 | AH17: =IF(A17=A16,0,(SUMIF($A$3:$A$999956,A17,($AC$3:$AC$999956)))) -> 0 | AK17: =AH17+AG17 -> 0
A18: 1115 | B18: =IF(A18=A17,B17+1,1) -> 1 | C18: 45112 | D18: Domanski Roberto | E18: =CONCATENATE(A18,D18,B18) -> 1115Domanski Roberto1 | F18: AE880MIT | G18: VW T CROOS | H18: 31686 | I18: Service cambio de aceite y filtro. | J18: =IF(A18=A17,CONCATENATE(J17," ",I18),I18) -> Service cambio de aceite y filtro. | L18: 1 | M18: Aceite motor 5w30 | N18: Taller | Q18: 2112 | R18: Service | S18: =+(W18-Q18)/Q18 -> 1.6041667 | T18: 4.5 | W18: 5500 | X18: =W18*T18 -> 24750 | AC18: =+AB18*Y18 -> 0 | AD18: =IF(A18=A17,AD17+AC18,AC18) -> 0 | AE18: =+(Q18)*T18 -> 9504 | AF18: =IF(A18=A17,0,(SUMIF($A$3:$A$999956,A18,$AE$3:$AE$999956))) -> 15004 | AG18: =IF(A18=A17,0,(SUMIF($A$3:$A$999956,A18,($X$3:$X$999956)))) -> 36350 | AH18: =IF(A18=A17,0,(SUMIF($A$3:$A$999956,A18,($AC$3:$AC$999956)))) -> 22000 | AK18: =AH18+AG18 -> 58350
A19: 1115 | B19: =IF(A19=A18,B18+1,1) -> 2 | C19: =IF(A19=A18,C18,"") -> 45112 | D19: =IF(A19=A18,D18,"") -> Domanski Roberto | E19: =CONCATENATE(A19,D19,B19) -> 1115Domanski Roberto2 | I19: Rotación de ruedas. | J19: =IF(A19=A18,CONCATENATE(J18," ",I19),I19) -> Service cambio de aceite y filtro. Rotación de ruedas. | L19: 1 | M19: Filtro aceite | N19: Taller | Q19: 1500 | S19: =+(W19-Q19)/Q19 -> 1.5333333 | T19: 1 | W19: 3800 | X19: =W19*T19 -> 3800 | AC19: =+AB19*Y19 -> 0 | AD19: =IF(A19=A18,AD18+AC19,AC19) -> 0 | AE19: =+(Q19)*T19 -> 1500 | AF19: =IF(A19=A18,0,(SUMIF($A$3:$A$999956,A19,$AE$3:$AE$999956))) -> 0 | AG19: =IF(A19=A18,0,(SUMIF($A$3:$A$999956,A19,($X$3:$X$999956)))) -> 0 | AH19: =IF(A19=A18,0,(SUMIF($A$3:$A$999956,A19,($AC$3:$AC$999956)))) -> 0 | AK19: =AH19+AG19 -> 0
A20: 1115 | B20: =IF(A20=A19,B19+1,1) -> 3 | C20: =IF(A20=A19,C19,"") -> 45112 | D20: =IF(A20=A19,D19,"") -> Domanski Roberto | E20: =CONCATENATE(A20,D20,B20) -> 1115Domanski Roberto3 | J20: =IF(A20=A19,CONCATENATE(J19," ",I20),I20) -> Service cambio de aceite y filtro. Rotación de ruedas. | L20: 1 | M20: Filtro aire | N20: Taller | Q20: 2000 | S20: =+(W20-Q20)/Q20 -> 1.4 | T20: 1 | W20: 4800 | X20: =W20*T20 -> 4800 | AC20: =+AB20*Y20 -> 0 | AD20: =IF(A20=A19,AD19+AC20,AC20) -> 0 | AE20: =+(Q20)*T20 -> 2000 | AF20: =IF(A20=A19,0,(SUMIF($A$3:$A$999956,A20,$AE$3:$AE$999956))) -> 0 | AG20: =IF(A20=A19,0,(SUMIF($A$3:$A$999956,A20,($X$3:$X$999956)))) -> 0 | AH20: =IF(A20=A19,0,(SUMIF($A$3:$A$999956,A20,($AC$3:$AC$999956)))) -> 0 | AK20: =AH20+AG20 -> 0
A21: 1115 | B21: =IF(A21=A20,B20+1,1) -> 4 | C21: =IF(A21=A20,C20,"") -> 45112 | D21: =IF(A21=A20,D20,"") -> Domanski Roberto | E21: =CONCATENATE(A21,D21,B21) -> 1115Domanski Roberto4 | J21: =IF(A21=A20,CONCATENATE(J20," ",I21),I21) -> Service cambio de aceite y filtro. Rotación de ruedas. | L21: 1 | M21: Filtro pólen | N21: Taller | Q21: =+W21/(1+S21) -> 2000 | S21: 0.5 | T21: 1 | W21: 3000 | X21: =W21*T21 -> 3000 | AC21: =+AB21*Y21 -> 0 | AD21: =IF(A21=A20,AD20+AC21,AC21) -> 0 | AE21: =+(Q21)*T21 -> 2000 | AF21: =IF(A21=A20,0,(SUMIF($A$3:$A$999956,A21,$AE$3:$AE$999956))) -> 0 | AG21: =IF(A21=A20,0,(SUMIF($A$3:$A$999956,A21,($X$3:$X$999956)))) -> 0 | AH21: =IF(A21=A20,0,(SUMIF($A$3:$A$999956,A21,($AC$3:$AC$999956)))) -> 0 | AK21: =AH21+AG21 -> 0
A22: 1115 | B22: =IF(A22=A21,B21+1,1) -> 5 | C22: =IF(A22=A21,C21,"") -> 45112 | D22: =IF(A22=A21,D21,"") -> Domanski Roberto | E22: =CONCATENATE(A22,D22,B22) -> 1115Domanski Roberto5 | J22: =IF(A22=A21,CONCATENATE(J21," ",I22),I22) -> Service cambio de aceite y filtro. Rotación de ruedas. | L22: 1 | W22: 0 | X22: =W22*T22 -> 0 | AC22: =+AB22*Y22 -> 0 | AD22: =IF(A22=A21,AD21+AC22,AC22) -> 0 | AE22: =+(Q22)*T22 -> 0 | AF22: =IF(A22=A21,0,(SUMIF($A$3:$A$999956,A22,$AE$3:$AE$999956))) -> 0 | AG22: =IF(A22=A21,0,(SUMIF($A$3:$A$999956,A22,($X$3:$X$999956)))) -> 0 | AH22: =IF(A22=A21,0,(SUMIF($A$3:$A$999956,A22,($AC$3:$AC$999956)))) -> 0 | AK22: =AH22+AG22 -> 0
A23: 1115 | B23: =IF(A23=A22,B22+1,1) -> 6 | C23: =IF(A23=A22,C22,"") -> 45112 | D23: =IF(A23=A22,D22,"") -> Domanski Roberto | E23: =CONCATENATE(A23,D23,B23) -> 1115Domanski Roberto6 | J23: =IF(A23=A22,CONCATENATE(J22," ",I23),I23) -> Service cambio de aceite y filtro. Rotación de ruedas. | L23: 1 | W23: 0 | X23: =W23*T23 -> 0 | Y23: 1 | AB23: 22000 | AC23: =+AB23*Y23 -> 22000 | AD23: =IF(A23=A22,AD22+AC23,AC23) -> 22000 | AE23: =+(Q23)*T23 -> 0 | AF23: =IF(A23=A22,0,(SUMIF($A$3:$A$999956,A23,$AE$3:$AE$999956))) -> 0 | AG23: =IF(A23=A22,0,(SUMIF($A$3:$A$999956,A23,($X$3:$X$999956)))) -> 0 | AH23: =IF(A23=A22,0,(SUMIF($A$3:$A$999956,A23,($AC$3:$AC$999956)))) -> 0 | AK23: =AH23+AG23 -> 0
A24: 1116 | B24: =IF(A24=A23,B23+1,1) -> 1 | C24: 45112 | D24: Quiroga Hector | E24: =CONCATENATE(A24,D24,B24) -> 1116Quiroga Hector1 | F24: AA914VK | G24: GolTrend | H24: 55440 | I24: Service cambio de aceite y filtro. | J24: =IF(A24=A23,CONCATENATE(J23," ",I24),I24) -> Service cambio de aceite y filtro. | L24: 1 | M24: Filtro aceite | N24: Taller | Q24: 3000 | R24: Service | S24: 1 | T24: 1 | W24: 3000 | X24: =W24*T24 -> 3000 | AC24: =+AB24*Y24 -> 0 | AD24: =IF(A24=A23,AD23+AC24,AC24) -> 0 | AE24: =+(Q24)*T24 -> 3000 | AF24: =IF(A24=A23,0,(SUMIF($A$3:$A$999956,A24,$AE$3:$AE$999956))) -> 59127.333 | AG24: =IF(A24=A23,0,(SUMIF($A$3:$A$999956,A24,($X$3:$X$999956)))) -> 77900 | AH24: =IF(A24=A23,0,(SUMIF($A$3:$A$999956,A24,($AC$3:$AC$999956)))) -> 50000 | AK24: =AH24+AG24 -> 127900
A25: 1116 | B25: =IF(A25=A24,B24+1,1) -> 2 | C25: =IF(A25=A24,C24,"") -> 45112 | D25: =IF(A25=A24,D24,"") -> Quiroga Hector | E25: =CONCATENATE(A25,D25,B25) -> 1116Quiroga Hector2 | I25: Control del véhiculo. | J25: =IF(A25=A24,CONCATENATE(J24," ",I25),I25) -> Service cambio de aceite y filtro. Control del véhiculo. | L25: 1 | M25: Filtro aire | N25: Taller | Q25: 2000 | S25: =+(W25-Q25)/Q25 -> 1 | T25: 1 | W25: 4000 | X25: =W25*T25 -> 4000 | AC25: =+AB25*Y25 -> 0 | AD25: =IF(A25=A24,AD24+AC25,AC25) -> 0 | AE25: =+(Q25)*T25 -> 2000 | AF25: =IF(A25=A24,0,(SUMIF($A$3:$A$999956,A25,$AE$3:$AE$999956))) -> 0 | AG25: =IF(A25=A24,0,(SUMIF($A$3:$A$999956,A25,($X$3:$X$999956)))) -> 0 | AH25: =IF(A25=A24,0,(SUMIF($A$3:$A$999956,A25,($AC$3:$AC$999956)))) -> 0 | AK25: =AH25+AG25 -> 0
A26: 1116 | B26: =IF(A26=A25,B25+1,1) -> 3 | C26: =IF(A26=A25,C25,"") -> 45112 | D26: =IF(A26=A25,D25,"") -> Quiroga Hector | E26: =CONCATENATE(A26,D26,B26) -> 1116Quiroga Hector3 | I26: Rotación de ruedas. | J26: =IF(A26=A25,CONCATENATE(J25," ",I26),I26) -> Service cambio de aceite y filtro. Control del véhiculo. Rotación de ruedas. | L26: 1 | M26: Filtro nafta | N26: Taller | Q26: 2000 | S26: =+(W26-Q26)/Q26 -> 0.6 | T26: 1 | W26: 3200 | X26: =W26*T26 -> 3200 | AC26: =+AB26*Y26 -> 0 | AD26: =IF(A26=A25,AD25+AC26,AC26) -> 0 | AE26: =+(Q26)*T26 -> 2000 | AF26: =IF(A26=A25,0,(SUMIF($A$3:$A$999956,A26,$AE$3:$AE$999956))) -> 0 | AG26: =IF(A26=A25,0,(SUMIF($A$3:$A$999956,A26,($X$3:$X$999956)))) -> 0 | AH26: =IF(A26=A25,0,(SUMIF($A$3:$A$999956,A26,($AC$3:$AC$999956)))) -> 0 | AK26: =AH26+AG26 -> 0
A27: 1116 | B27: =IF(A27=A26,B26+1,1) -> 4 | C27: =IF(A27=A26,C26,"") -> 45112 | D27: =IF(A27=A26,D26,"") -> Quiroga Hector | E27: =CONCATENATE(A27,D27,B27) -> 1116Quiroga Hector4 | I27: Cambio de kit completo de distribución y correa poliv. | J27: =IF(A27=A26,CONCATENATE(J26," ",I27),I27) -> Service cambio de aceite y filtro. Control del véhiculo. Rotación de ruedas. Cambio de kit completo de distribución y correa poliv. | L27: 1 | M27: Filtro pólen | N27: Taller | Q27: =+W27/(1+S27) -> 2000 | S27: 0.5 | T27: 1 | W27: 3000 | X27: =W27*T27 -> 3000 | AC27: =+AB27*Y27 -> 0 | AD27: =IF(A27=A26,AD26+AC27,AC27) -> 0 | AE27: =+(Q27)*T27 -> 2000 | AF27: =IF(A27=A26,0,(SUMIF($A$3:$A$999956,A27,$AE$3:$AE$999956))) -> 0 | AG27: =IF(A27=A26,0,(SUMIF($A$3:$A$999956,A27,($X$3:$X$999956)))) -> 0 | AH27: =IF(A27=A26,0,(SUMIF($A$3:$A$999956,A27,($AC$3:$AC$999956)))) -> 0 | AK27: =AH27+AG27 -> 0
A28: 1116 | B28: =IF(A28=A27,B27+1,1) -> 5 | C28: =IF(A28=A27,C27,"") -> 45112 | D28: =IF(A28=A27,D27,"") -> Quiroga Hector | E28: =CONCATENATE(A28,D28,B28) -> 1116Quiroga Hector5 | I28: Cambio de bomba de agua. | J28: =IF(A28=A27,CONCATENATE(J27," ",I28),I28) -> Service cambio de aceite y filtro. Control del véhiculo. Rotación de ruedas. Cambio de kit completo de distribución y correa poliv. Cambio de bomba de agua. | L28: 1 | M28: Kit distribución con bomba de agua y correa poliv. | N28: Taller | Q28: =+W28/(1+S28) -> 48333.333 | S28: 0.2 | T28: 1 | W28: 58000 | X28: =W28*T28 -> 58000 | AC28: =+AB28*Y28 -> 0 | AD28: =IF(A28=A27,AD27+AC28,AC28) -> 0 | AE28: =+(Q28)*T28 -> 48333.333 | AF28: =IF(A28=A27,0,(SUMIF($A$3:$A$999956,A28,$AE$3:$AE$999956))) -> 0 | AG28: =IF(A28=A27,0,(SUMIF($A$3:$A$999956,A28,($X$3:$X$999956)))) -> 0 | AH28: =IF(A28=A27,0,(SUMIF($A$3:$A$999956,A28,($AC$3:$AC$999956)))) -> 0 | AK28: =AH28+AG28 -> 0
A29: 1116 | B29: =IF(A29=A28,B28+1,1) -> 6 | C29: =IF(A29=A28,C28,"") -> 45112 | D29: =IF(A29=A28,D28,"") -> Quiroga Hector | E29: =CONCATENATE(A29,D29,B29) -> 1116Quiroga Hector6 | J29: =IF(A29=A28,CONCATENATE(J28," ",I29),I29) -> Service cambio de aceite y filtro. Control del véhiculo. Rotación de ruedas. Cambio de kit completo de distribución y correa poliv. Cambio de bomba de agua. | L29: 1 | M29: Liquido refrigerante + agua destilada | N29: Taller | Q29: 1794 | S29: =+(W29-Q29)/Q29 -> 2.7346711 | T29: 1 | W29: 6700 | X29: =W29*T29 -> 6700 | Y29: 1 | AB29: 50000 | AC29: =+AB29*Y29 -> 50000 | AD29: =IF(A29=A28,AD28+AC29,AC29) -> 50000 | AE29: =+(Q29)*T29 -> 1794 | AF29: =IF(A29=A28,0,(SUMIF($A$3:$A$999956,A29,$AE$3:$AE$999956))) -> 0 | AG29: =IF(A29=A28,0,(SUMIF($A$3:$A$999956,A29,($X$3:$X$999956)))) -> 0 | AH29: =IF(A29=A28,0,(SUMIF($A$3:$A$999956,A29,($AC$3:$AC$999956)))) -> 0 | AK29: =AH29+AG29 -> 0
A30: 1117 | B30: =IF(A30=A29,B29+1,1) -> 1 | C30: 45112 | D30: Pisani Nicolas | E30: =CONCATENATE(A30,D30,B30) -> 1117Pisani Nicolas1 | G30: Megane | I30: Sacar tapa válvula. | J30: =IF(A30=A29,CONCATENATE(J29," ",I30),I30) -> Sacar tapa válvula. | L30: 1 | M30: Retenes de arboles de leva | N30: Barotto | Q30: =3900*0.8 -> 3120 | R30: Otros | S30: =+(W30-Q30)/Q30 -> 0.25 | T30: 2 | W30: 3900 | X30: =W30*T30 -> 7800 | AC30: =+AB30*Y30 -> 0 | AD30: =IF(A30=A29,AD29+AC30,AC30) -> 0 | AE30: =+(Q30)*T30 -> 6240 | AF30: =IF(A30=A29,0,(SUMIF($A$3:$A$999956,A30,$AE$3:$AE$999956))) -> 13008 | AG30: =IF(A30=A29,0,(SUMIF($A$3:$A$999956,A30,($X$3:$X$999956)))) -> 16260 | AH30: =IF(A30=A29,0,(SUMIF($A$3:$A$999956,A30,($AC$3:$AC$999956)))) -> 35000 | AK30: =AH30+AG30 -> 51260
A31: 1117 | B31: =IF(A31=A30,B30+1,1) -> 2 | C31: =IF(A31=A30,C30,"") -> 45112 | D31: =IF(A31=A30,D30,"") -> Pisani Nicolas | E31: =CONCATENATE(A31,D31,B31) -> 1117Pisani Nicolas2 | I31: Limpieza y armado con sellador nuevo. | J31: =IF(A31=A30,CONCATENATE(J30," ",I31),I31) -> Sacar tapa válvula. Limpieza y armado con sellador nuevo. | L31: 1 | M31: Correa poliv | N31: Ferrando | Q31: =8460*0.8 -> 6768 | S31: =+(W31-Q31)/Q31 -> 0.25 | T31: 1 | W31: 8460 | X31: =W31*T31 -> 8460 | Y31: 1 | AB31: 35000 | AC31: =+AB31*Y31 -> 35000 | AD31: =IF(A31=A30,AD30+AC31,AC31) -> 35000 | AE31: =+(Q31)*T31 -> 6768 | AF31: =IF(A31=A30,0,(SUMIF($A$3:$A$999956,A31,$AE$3:$AE$999956))) -> 0 | AG31: =IF(A31=A30,0,(SUMIF($A$3:$A$999956,A31,($X$3:$X$999956)))) -> 0 | AH31: =IF(A31=A30,0,(SUMIF($A$3:$A$999956,A31,($AC$3:$AC$999956)))) -> 0 | AK31: =AH31+AG31 -> 0
A32: 1117 | B32: =IF(A32=A31,B31+1,1) -> 3 | C32: =IF(A32=A31,C31,"") -> 45112 | D32: =IF(A32=A31,D31,"") -> Pisani Nicolas | E32: =CONCATENATE(A32,D32,B32) -> 1117Pisani Nicolas3 | I32: Cambiar orring cuerpo mariposa. | J32: =IF(A32=A31,CONCATENATE(J31," ",I32),I32) -> Sacar tapa válvula. Limpieza y armado con sellador nuevo. Cambiar orring cuerpo mariposa. | L32: 1 | W32: 0 | X32: =W32*T32 -> 0 | AC32: =+AB32*Y32 -> 0 | AD32: =IF(A32=A31,AD31+AC32,AC32) -> 35000 | AE32: =+(Q32)*T32 -> 0 | AF32: =IF(A32=A31,0,(SUMIF($A$3:$A$999956,A32,$AE$3:$AE$999956))) -> 0 | AG32: =IF(A32=A31,0,(SUMIF($A$3:$A$999956,A32,($X$3:$X$999956)))) -> 0 | AH32: =IF(A32=A31,0,(SUMIF($A$3:$A$999956,A32,($AC$3:$AC$999956)))) -> 0 | AK32: =AH32+AG32 -> 0
A33: 1117 | B33: =IF(A33=A32,B32+1,1) -> 4 | C33: =IF(A33=A32,C32,"") -> 45112 | D33: =IF(A33=A32,D32,"") -> Pisani Nicolas | E33: =CONCATENATE(A33,D33,B33) -> 1117Pisani Nicolas4 | I33: Correa poliv. | J33: =IF(A33=A32,CONCATENATE(J32," ",I33),I33) -> Sacar tapa válvula. Limpieza y armado con sellador nuevo. Cambiar orring cuerpo mariposa. Correa poliv. | L33: 1 | W33: 0 | X33: =W33*T33 -> 0 | AC33: =+AB33*Y33 -> 0 | AD33: =IF(A33=A32,AD32+AC33,AC33) -> 35000 | AE33: =+(Q33)*T33 -> 0 | AF33: =IF(A33=A32,0,(SUMIF($A$3:$A$999956,A33,$AE$3:$AE$999956))) -> 0 | AG33: =IF(A33=A32,0,(SUMIF($A$3:$A$999956,A33,($X$3:$X$999956)))) -> 0 | AH33: =IF(A33=A32,0,(SUMIF($A$3:$A$999956,A33,($AC$3:$AC$999956)))) -> 0 | AK33: =AH33+AG33 -> 0
A34: 1117 | B34: =IF(A34=A33,B33+1,1) -> 5 | C34: =IF(A34=A33,C33,"") -> 45112 | D34: =IF(A34=A33,D33,"") -> Pisani Nicolas | E34: =CONCATENATE(A34,D34,B34) -> 1117Pisani Nicolas5 | I34: Retenes de árboles de leva. | J34: =IF(A34=A33,CONCATENATE(J33," ",I34),I34) -> Sacar tapa válvula. Limpieza y armado con sellador nuevo. Cambiar orring cuerpo mariposa. Correa poliv. Retenes de árboles de leva. | L34: 1 | W34: 0 | X34: =W34*T34 -> 0 | AC34: =+AB34*Y34 -> 0 | AD34: =IF(A34=A33,AD33+AC34,AC34) -> 35000 | AE34: =+(Q34)*T34 -> 0 | AF34: =IF(A34=A33,0,(SUMIF($A$3:$A$999956,A34,$AE$3:$AE$999956))) -> 0 | AG34: =IF(A34=A33,0,(SUMIF($A$3:$A$999956,A34,($X$3:$X$999956)))) -> 0 | AH34: =IF(A34=A33,0,(SUMIF($A$3:$A$999956,A34,($AC$3:$AC$999956)))) -> 0 | AK34: =AH34+AG34 -> 0
A35: 1117 | B35: =IF(A35=A34,B34+1,1) -> 6 | C35: =IF(A35=A34,C34,"") -> 45112 | D35: =IF(A35=A34,D34,"") -> Pisani Nicolas | E35: =CONCATENATE(A35,D35,B35) -> 1117Pisani Nicolas6 | I35: Puesta a punto. Armado total. | J35: =IF(A35=A34,CONCATENATE(J34," ",I35),I35) -> Sacar tapa válvula. Limpieza y armado con sellador nuevo. Cambiar orring cuerpo mariposa. Correa poliv. Retenes de árboles de leva. Puesta a punto. Armado total. | L35: 1 | W35: 0 | X35: =W35*T35 -> 0 | AC35: =+AB35*Y35 -> 0 | AD35: =IF(A35=A34,AD34+AC35,AC35) -> 35000 | AE35: =+(Q35)*T35 -> 0 | AF35: =IF(A35=A34,0,(SUMIF($A$3:$A$999956,A35,$AE$3:$AE$999956))) -> 0 | AG35: =IF(A35=A34,0,(SUMIF($A$3:$A$999956,A35,($X$3:$X$999956)))) -> 0 | AH35: =IF(A35=A34,0,(SUMIF($A$3:$A$999956,A35,($AC$3:$AC$999956)))) -> 0 | AK35: =AH35+AG35 -> 0
A36: 1118 | B36: =IF(A36=A35,B35+1,1) -> 1 | C36: 45112 | D36: Acotto Jorge | E36: =CONCATENATE(A36,D36,B36) -> 1118Acotto Jorge1 | G36: 147 | I36: Desarmar suspensión lado derecho. | J36: =IF(A36=A35,CONCATENATE(J35," ",I36),I36) -> Desarmar suspensión lado derecho. | L36: 1 | M36: Aceite caja velocidad | N36: Taller | Q36: =+W36/(1+S36) -> 3076.9231 | R36: Otros | S36: 1.6 | T36: 1 | W36: 8000 | X36: =W36*T36 -> 8000 | AC36: =+AB36*Y36 -> 0 | AD36: =IF(A36=A35,AD35+AC36,AC36) -> 0 | AE36: =+(Q36)*T36 -> 3076.9231 | AF36: =IF(A36=A35,0,(SUMIF($A$3:$A$999956,A36,$AE$3:$AE$999956))) -> 6308.9231 | AG36: =IF(A36=A35,0,(SUMIF($A$3:$A$999956,A36,($X$3:$X$999956)))) -> 12040 | AH36: =IF(A36=A35,0,(SUMIF($A$3:$A$999956,A36,($AC$3:$AC$999956)))) -> 20000 | AK36: =AH36+AG36 -> 32040
A37: 1118 | B37: =IF(A37=A36,B36+1,1) -> 2 | C37: =IF(A37=A36,C36,"") -> 45112 | D37: =IF(A37=A36,D36,"") -> Acotto Jorge | E37: =CONCATENATE(A37,D37,B37) -> 1118Acotto Jorge2 | I37: Colocar grasa y abrazaderas nuevas en fuelle de homocinética. | J37: =IF(A37=A36,CONCATENATE(J36," ",I37),I37) -> Desarmar suspensión lado derecho. Colocar grasa y abrazaderas nuevas en fuelle de homocinética. | L37: 1 | M37: Fuelle semi eje lado caja izquierdo | N37: Rep Serrano | Q37: =1830*0.8 -> 1464 | S37: =+(W37-Q37)/Q37 -> 0.25 | T37: 1 | W37: 1830 | X37: =W37*T37 -> 1830 | AC37: =+AB37*Y37 -> 0 | AD37: =IF(A37=A36,AD36+AC37,AC37) -> 0 | AE37: =+(Q37)*T37 -> 1464 | AF37: =IF(A37=A36,0,(SUMIF($A$3:$A$999956,A37,$AE$3:$AE$999956))) -> 0 | AG37: =IF(A37=A36,0,(SUMIF($A$3:$A$999956,A37,($X$3:$X$999956)))) -> 0 | AH37: =IF(A37=A36,0,(SUMIF($A$3:$A$999956,A37,($AC$3:$AC$999956)))) -> 0 | AK37: =AH37+AG37 -> 0
A38: 1118 | B38: =IF(A38=A37,B37+1,1) -> 3 | C38: =IF(A38=A37,C37,"") -> 45112 | D38: =IF(A38=A37,D37,"") -> Acotto Jorge | E38: =CONCATENATE(A38,D38,B38) -> 1118Acotto Jorge3 | I38: Desarmar suspensión lado izquierdo. | J38: =IF(A38=A37,CONCATENATE(J37," ",I38),I38) -> Desarmar suspensión lado derecho. Colocar grasa y abrazaderas nuevas en fuelle de homocinética. Desarmar suspensión lado izquierdo. | L38: 1 | M38: Reten eje selector | N38: Ferrando | Q38: =1000*0.8 -> 800 | S38: =+(W38-Q38)/Q38 -> 0.25 | T38: 1 | W38: 1000 | X38: =W38*T38 -> 1000 | AC38: =+AB38*Y38 -> 0 | AD38: =IF(A38=A37,AD37+AC38,AC38) -> 0 | AE38: =+(Q38)*T38 -> 800 | AF38: =IF(A38=A37,0,(SUMIF($A$3:$A$999956,A38,$AE$3:$AE$999956))) -> 0 | AG38: =IF(A38=A37,0,(SUMIF($A$3:$A$999956,A38,($X$3:$X$999956)))) -> 0 | AH38: =IF(A38=A37,0,(SUMIF($A$3:$A$999956,A38,($AC$3:$AC$999956)))) -> 0 | AK38: =AH38+AG38 -> 0
A39: 1118 | B39: =IF(A39=A38,B38+1,1) -> 4 | C39: =IF(A39=A38,C38,"") -> 45112 | D39: =IF(A39=A38,D38,"") -> Acotto Jorge | E39: =CONCATENATE(A39,D39,B39) -> 1118Acotto Jorge4 | I39: Sacar semi eje. | J39: =IF(A39=A38,CONCATENATE(J38," ",I39),I39) -> Desarmar suspensión lado derecho. Colocar grasa y abrazaderas nuevas en fuelle de homocinética. Desarmar suspensión lado izquierdo. Sacar semi eje. | L39: 1 | M39: Fuelle de reten de eje selector | N39: Rep Serrano | Q39: =1210*0.8 -> 968 | S39: =+(W39-Q39)/Q39 -> 0.25 | T39: 1 | W39: 1210 | X39: =W39*T39 -> 1210 | AC39: =+AB39*Y39 -> 0 | AD39: =IF(A39=A38,AD38+AC39,AC39) -> 0 | AE39: =+(Q39)*T39 -> 968 | AF39: =IF(A39=A38,0,(SUMIF($A$3:$A$999956,A39,$AE$3:$AE$999956))) -> 0 | AG39: =IF(A39=A38,0,(SUMIF($A$3:$A$999956,A39,($X$3:$X$999956)))) -> 0 | AH39: =IF(A39=A38,0,(SUMIF($A$3:$A$999956,A39,($AC$3:$AC$999956)))) -> 0 | AK39: =AH39+AG39 -> 0
A40: 1118 | B40: =IF(A40=A39,B39+1,1) -> 5 | C40: =IF(A40=A39,C39,"") -> 45112 | D40: =IF(A40=A39,D39,"") -> Acotto Jorge | E40: =CONCATENATE(A40,D40,B40) -> 1118Acotto Jorge5 | I40: Reparar con fuelle lado caja nueva. | J40: =IF(A40=A39,CONCATENATE(J39," ",I40),I40) -> Desarmar suspensión lado derecho. Colocar grasa y abrazaderas nuevas en fuelle de homocinética. Desarmar suspensión lado izquierdo. Sacar semi eje. Reparar con fuelle lado caja nueva. | L40: 1 | W40: 0 | X40: =W40*T40 -> 0 | Y40: 1 | AB40: 20000 | AC40: =+AB40*Y40 -> 20000 | AD40: =IF(A40=A39,AD39+AC40,AC40) -> 20000 | AE40: =+(Q40)*T40 -> 0 | AF40: =IF(A40=A39,0,(SUMIF($A$3:$A$999956,A40,$AE$3:$AE$999956))) -> 0 | AG40: =IF(A40=A39,0,(SUMIF($A$3:$A$999956,A40,($X$3:$X$999956)))) -> 0 | AH40: =IF(A40=A39,0,(SUMIF($A$3:$A$999956,A40,($AC$3:$AC$999956)))) -> 0 | AK40: =AH40+AG40 -> 0
...

Sheet Ficha
A1: Deuda por cliente | E1: Deuda cliente por fecha | H1: Cliente | I1: Transporte Palloni | Q1: Cliente | R1: Transporte Palloni
A2: Antes de analizar apretar click derecho sobre la tabla y luego "Actualizar" | E2: Antes de analizar apretar click derecho sobre la tabla y luego "Actualizar" | Q2: Fecha | R2: (Varios elementos)
E3: Están agrupados por cantidad de meses de deuda | H3: Etiquetas de fila | I3: Suma de Total trabajo | J3: Suma de Entrega 1 | K3: Suma de Fecha 1 | L3: Suma de Entrega 2 | M3: Suma de Fecha 2
H4: 1334 | I4: 25000 | J4: 25000 | K4: 45180 | O4: Dominio | P4: Vehículo | Q4: Etiquetas de fila | R4: Suma de Total precio repuesto | S4: Suma de Total MO | T4: Suma de Total trabajo
A5: Deuda | B5: (Varios elementos) | E5: Deuda | F5: (Varios elementos) | H5: 1336 | I5: 50000 | J5: 50000 | K5: 45180 | O5: =IFERROR(VLOOKUP(Q5,'Carga Remito.'!A$9:G$23287,6,0),"") -> 993CE | P5: =IFERROR(VLOOKUP(Q5,'Carga Remito.'!A$9:H$23287,7,0),"") -> Fiorino | Q5: 1112 | R5: 0 | S5: 7000 | T5: 7000
H6: 1341 | I6: 7000 | J6: 7000 | K6: 45180 | O6: =IFERROR(VLOOKUP(Q6,'Carga Remito.'!A$9:G$23287,6,0),"") | P6: =IFERROR(VLOOKUP(Q6,'Carga Remito.'!A$9:H$23287,7,0),"") | Q6: Cambiar cables de bujias y bujias. | R6: 0 | S6: 7000 | T6: 7000
A7: Etiquetas de fila | B7: Suma de Deuda | E7: Etiquetas de fila | F7: Suma de Deuda | H7: 1345 | I7: 0 | O7: =IFERROR(VLOOKUP(Q7,'Carga Remito.'!A$9:G$23287,6,0),"") -> 0 | P7: =IFERROR(VLOOKUP(Q7,'Carga Remito.'!A$9:H$23287,7,0),"") -> Peugeot 208 | Q7: 1113 | R7: 26400 | S7: 18000 | T7: 44400
A8: Acotto Jorge | B8: 0 | E8: 0 | F8: 11041240 | H8: 1349 | I8: 45000 | J8: 45000 | K8: 45180 | O8: =IFERROR(VLOOKUP(Q8,'Carga Remito.'!A$9:G$23287,6,0),"") | P8: =IFERROR(VLOOKUP(Q8,'Carga Remito.'!A$9:H$23287,7,0),"") | Q8: Control del vehículo. | R8: 0 | S8: 0 | T8: 0
A9: Antonio Orsa | B9: 0 | E9: Altamirano Alicia | F9: 270750 | H9: 1355 | I9: 0 | O9: =IFERROR(VLOOKUP(Q9,'Carga Remito.'!A$9:G$23287,6,0),"") | P9: =IFERROR(VLOOKUP(Q9,'Carga Remito.'!A$9:H$23287,7,0),"") | Q9: Rotación de ruedas. | R9: 0 | S9: 0 | T9: 0
A10: Baner Abu Grillo | B10: 0 | E10: Carranza Mauro | F10: 686000 | H10: 1360 | I10: 0 | O10: =IFERROR(VLOOKUP(Q10,'Carga Remito.'!A$9:G$23287,6,0),"") | P10: =IFERROR(VLOOKUP(Q10,'Carga Remito.'!A$9:H$23287,7,0),"") | Q10: Service cambio de aceite y filtros. | R10: 26400 | S10: 18000 | T10: 44400
A11: Beriani Nazarena | B11: 0 | E11: Cometto Julia | F11: 120000 | H11: 1369 | I11: 0 | O11: =IFERROR(VLOOKUP(Q11,'Carga Remito.'!A$9:G$23287,6,0),"") | P11: =IFERROR(VLOOKUP(Q11,'Carga Remito.'!A$9:H$23287,7,0),"") | Q11: (en blanco) | R11: 0 | S11: 0 | T11: 0
A12: Bertaina Damian | B12: 0 | E12: Cosaro Juan | F12: 186000 | H12: 1378 | I12: 4000 | J12: 4000 | O12: =IFERROR(VLOOKUP(Q12,'Carga Remito.'!A$9:G$23287,6,0),"") -> 553 | P12: =IFERROR(VLOOKUP(Q12,'Carga Remito.'!A$9:H$23287,7,0),"") -> 0 | Q12: 1163 | R12: 0 | S12: 30000 | T12: 30000
A13: Bustos Lolo | B13: 0 | E13: Dondena Cristian | F13: 149500 | H13: 1381 | I13: 30000 | J13: 30000 | O13: =IFERROR(VLOOKUP(Q13,'Carga Remito.'!A$9:G$23287,6,0),"") | P13: =IFERROR(VLOOKUP(Q13,'Carga Remito.'!A$9:H$23287,7,0),"") | Q13: Cambiar kit bomba de agua. | R13: 0 | S13: 0 | T13: 0
A14: Cabral Guillermo | B14: 0 | E14: Integral Agropecuaria | F14: 1019500 | H14: 1398 | I14: 6000 | J14: 6000 | K14: 45189 | O14: =IFERROR(VLOOKUP(Q14,'Carga Remito.'!A$9:G$23287,6,0),"") | P14: =IFERROR(VLOOKUP(Q14,'Carga Remito.'!A$9:H$23287,7,0),"") | Q14: Cambio de aceite y filtros. | R14: 0 | S14: 30000 | T14: 30000
A15: Fernandez Gerardo | B15: 0 | E15: Isasi Luciana | F15: 489500 | H15: 1402 | I15: 35000 | J15: 35000 | O15: =IFERROR(VLOOKUP(Q15,'Carga Remito.'!A$9:G$23287,6,0),"") | P15: =IFERROR(VLOOKUP(Q15,'Carga Remito.'!A$9:H$23287,7,0),"") | Q15: Desarmar distribución completa. | R15: 0 | S15: 0 | T15: 0
A16: Formini Victor | B16: 0 | E16: Maan constructora | F16: 300000 | H16: 1407 | I16: 8000 | J16: 8000 | O16: =IFERROR(VLOOKUP(Q16,'Carga Remito.'!A$9:G$23287,6,0),"") | P16: =IFERROR(VLOOKUP(Q16,'Carga Remito.'!A$9:H$23287,7,0),"") | Q16: Liquido refrigerante, purgado del circuito refrigerante y cambiar correa poliv. | R16: 0 | S16: 0 | T16: 0
A17: Gigante Joni | B17: 0 | E17: Medic | F17: 260000 | H17: 1418 | I17: 8000 | J17: 8000 | O17: =IFERROR(VLOOKUP(Q17,'Carga Remito.'!A$9:G$23287,6,0),"") -> 703 | P17: =IFERROR(VLOOKUP(Q17,'Carga Remito.'!A$9:H$23287,7,0),"") -> Kangoo | Q17: 1164 | R17: 0 | S17: 100000 | T17: 100000
A18: Gonzalez Alberto | B18: 0 | E18: Moretti Anabella | F18: 700500 | H18: 1419 | I18: 11000 | J18: 11000 | K18: 45196 | O18: =IFERROR(VLOOKUP(Q18,'Carga Remito.'!A$9:G$23287,6,0),"") | P18: =IFERROR(VLOOKUP(Q18,'Carga Remito.'!A$9:H$23287,7,0),"") | Q18: Armado total. Puesta a punto. | R18: 0 | S18: 0 | T18: 0
A19: Guerrieri Gladys | B19: 0 | E19: Moretti Renato | F19: 805000 | H19: 1422 | I19: 15000 | J19: 15000 | O19: =IFERROR(VLOOKUP(Q19,'Carga Remito.'!A$9:G$23287,6,0),"") | P19: =IFERROR(VLOOKUP(Q19,'Carga Remito.'!A$9:H$23287,7,0),"") | Q19: Bomba de agua. | R19: 0 | S19: 0 | T19: 0
A20: Toyos Pato | B20: 0 | E20: Municipalidad Laboulaye | F20: 733500 | H20: 1427 | I20: 15000 | J20: 15000 | O20: =IFERROR(VLOOKUP(Q20,'Carga Remito.'!A$9:G$23287,6,0),"") | P20: =IFERROR(VLOOKUP(Q20,'Carga Remito.'!A$9:H$23287,7,0),"") | Q20: Cambiar líquido refrigerante. | R20: 0 | S20: 0 | T20: 0
A21: Hoyos Pato | B21: 0 | E21: Paredes Juan | F21: 891150 | H21: 1438 | I21: 12000 | J21: 12000 | K21: 45244 | O21: =IFERROR(VLOOKUP(Q21,'Carga Remito.'!A$9:G$23287,6,0),"") | P21: =IFERROR(VLOOKUP(Q21,'Carga Remito.'!A$9:H$23287,7,0),"") | Q21: Limpieza, colocar tapa de cilindro reparada. | R21: 0 | S21: 0 | T21: 0
A22: Irouleguy Daniel | B22: 0 | E22: Paz Jose Maria | F22: 215000 | H22: 1464 | I22: 95325 | J22: 95325 | K22: 45244 | O22: =IFERROR(VLOOKUP(Q22,'Carga Remito.'!A$9:G$23287,6,0),"") | P22: =IFERROR(VLOOKUP(Q22,'Carga Remito.'!A$9:H$23287,7,0),"") | Q22: Sacar tapa de cilindro íntegra. | R22: 0 | S22: 100000 | T22: 100000
A23: Isasi Luciana | B23: 0 | E23: Rodriguez Osvaldo | F23: 108800 | H23: 1465 | I23: 15000 | J23: 15000 | K23: 45244 | O23: =IFERROR(VLOOKUP(Q23,'Carga Remito.'!A$9:G$23287,6,0),"") -> AE993CF | P23: =IFERROR(VLOOKUP(Q23,'Carga Remito.'!A$9:H$23287,7,0),"") -> Fiorino | Q23: 1165 | R23: 0 | S23: 30000 | T23: 30000
A24: Juan Achabal | B24: 0 | E24: Salas Jesus | F24: 484600 | H24: 1480 | I24: 29000 | J24: 29000 | K24: 45244 | O24: =IFERROR(VLOOKUP(Q24,'Carga Remito.'!A$9:G$23287,6,0),"") | P24: =IFERROR(VLOOKUP(Q24,'Carga Remito.'!A$9:H$23287,7,0),"") | Q24: Armado total. | R24: 0 | S24: 0 | T24: 0
A25: Lang Juan Pablo | B25: 0 | E25: Transporte Palloni | F25: 121000 | H25: 1483 | I25: 42000 | J25: 42000 | K25: 45244 | O25: =IFERROR(VLOOKUP(Q25,'Carga Remito.'!A$9:G$23287,6,0),"") | P25: =IFERROR(VLOOKUP(Q25,'Carga Remito.'!A$9:H$23287,7,0),"") | Q25: Bomba de agua. Cambiar líquido refrigerante, purgado. | R25: 0 | S25: 0 | T25: 0
A26: Llanos Raquel | B26: 0 | E26: Giorgis Juan Carlos | F26: 265000 | H26: 1493 | I26: 6000 | J26: 6000 | K26: 45244 | O26: =IFERROR(VLOOKUP(Q26,'Carga Remito.'!A$9:G$23287,6,0),"") | P26: =IFERROR(VLOOKUP(Q26,'Carga Remito.'!A$9:H$23287,7,0),"") | Q26: Cambiar correa poliv y correas tensoras de alternador. | R26: 0 | S26: 0 | T26: 0
A27: Lucero Adrian | B27: 0 | E27: Gutierrez Hnos | F27: 1668000 | H27: 1497 | I27: 7000 | J27: 7000 | O27: =IFERROR(VLOOKUP(Q27,'Carga Remito.'!A$9:G$23287,6,0),"") | P27: =IFERROR(VLOOKUP(Q27,'Carga Remito.'!A$9:H$23287,7,0),"") | Q27: Desarmar distribución completa. Cambiar. | R27: 0 | S27: 30000 | T27: 30000
A28: Macagno Dante | B28: 0 | E28: Palloni Sirley | F28: 408000 | H28: 1501 | I28: 8000 | J28: 8000 | K28: 45244 | O28: =IFERROR(VLOOKUP(Q28,'Carga Remito.'!A$9:G$23287,6,0),"") | P28: =IFERROR(VLOOKUP(Q28,'Carga Remito.'!A$9:H$23287,7,0),"") | Q28: Puesta a punto. Cambiar bujias y cable de bujías. | R28: 0 | S28: 0 | T28: 0
A29: Macagno Omar | B29: 0 | E29: Costa Laura | F29: 155000 | H29: 1503 | I29: 7500 | J29: 7500 | O29: =IFERROR(VLOOKUP(Q29,'Carga Remito.'!A$9:G$23287,6,0),"") -> AF044MU | P29: =IFERROR(VLOOKUP(Q29,'Carga Remito.'!A$9:H$23287,7,0),"") -> Fiorino | Q29: 1166 | R29: 0 | S29: 28000 | T29: 28000
A30: Martin Jose | B30: 0 | E30: Monasterio Paola | F30: 266000 | H30: 1512 | I30: 48000 | J30: 48000 | K30: 45274 | O30: =IFERROR(VLOOKUP(Q30,'Carga Remito.'!A$9:G$23287,6,0),"") | P30: =IFERROR(VLOOKUP(Q30,'Carga Remito.'!A$9:H$23287,7,0),"") | Q30: Cambiar bomba de agua. | R30: 0 | S30: 0 | T30: 0
A31: Martinich Nahuel | B31: 0 | E31: Giovanini Laura | F31: 488840 | H31: 1513 | I31: 13000 | J31: 13000 | K31: 45274 | O31: =IFERROR(VLOOKUP(Q31,'Carga Remito.'!A$9:G$23287,6,0),"") | P31: =IFERROR(VLOOKUP(Q31,'Carga Remito.'!A$9:H$23287,7,0),"") | Q31: Desarmar distribución completa. | R31: 0 | S31: 28000 | T31: 28000
A32: Medic | B32: 0 | E32: Napoli Luciano | F32: 249600 | H32: 1516 | I32: 35000 | J32: 35000 | K32: 45274 | O32: =IFERROR(VLOOKUP(Q32,'Carga Remito.'!A$9:G$23287,6,0),"") | P32: =IFERROR(VLOOKUP(Q32,'Carga Remito.'!A$9:H$23287,7,0),"") | Q32: Purgado circuito de refrigeración. | R32: 0 | S32: 0 | T32: 0
A33: Muñoz | B33: 0 | E33: 2 | F33: 4867870 | H33: 1522 | I33: 19000 | J33: 19000 | K33: 45274 | O33: =IFERROR(VLOOKUP(Q33,'Carga Remito.'!A$9:G$23287,6,0),"") | P33: =IFERROR(VLOOKUP(Q33,'Carga Remito.'!A$9:H$23287,7,0),"") | Q33: Pusta a punto. Armado total. | R33: 0 | S33: 0 | T33: 0
